Workbook

Sheet 참가자
A1: 참가자 명단 — 실명·학번·연락처 금지. 무작위 참가자 코드만. (예시 12명은 가짜 데이터)
A2: 참가자 코드 | B2: 팀 | C2: 메모(선택, 개인정보 금지)
A3: K7QM | B3: 1팀
A4: R4XT | B4: 1팀
A5: H9WC | B5: 1팀
A6: B3NV | B6: 2팀
A7: Z8LD | B7: 2팀
A8: M2PF | B8: 2팀
A9: T6YH | B9: 3팀
A10: C5JR | B10: 3팀
A11: W3KE | B11: 3팀
A12: F8UA | B12: 4팀
A13: N4GS | B13: 4팀
A14: D7VB | B14: 4팀

Sheet 진단
A1: 진단 (1회차, 12문항) — 팀 편성 참고 + 일부러 못 보기 점검. 평가A가 없을 때만 기준점수로 대체 | L1: 붙여넣기 영역 (노란 칸, 3행부터)
A2: 참가자 코드 | B2: 팀 | C2: 정답률(%) | D2: 상태 | E2: 중복 점검 | L2: 참가자 코드 | M2: 맞힌 수 | N2: 문항 수 | O2: 정답률(%) | Q2: 정리된 코드(자동) | R2: 계산 정답률(자동) | S2: 비경쟁(자동) | T2: 명단 점검(자동)
A3: =IF(참가자!A3="","",UPPER(TRIM(참가자!A3))) -> K7QM | B3: =IF(A3="","",IF(참가자!B3="","(팀 없음)",TRIM(참가자!B3))) -> 1팀 | C3: =IF(A3="","",IFERROR(INDEX($R$3:$R$102,MATCH(A3,$Q$3:$Q$102,0)),"")) -> 50 | D3: =IF(A3="","",IF(C3="","결석",IF(IFERROR(INDEX($S$3:$S$102,MATCH(A3,$Q$3:$Q$102,0)),"")="비경쟁","비경쟁 응시","응시"))) -> 응시 | E3: =IF(A3="","",IF(COUNTIF($Q$3:$Q$102,A3)>1,"중복! 확인","")) | L3: K7QM | M3: 6 | N3: 12 | Q3: =IF(UPPER(TRIM(L3&""))="","",IF(RIGHT(UPPER(TRIM(L3&"")),2)="-N",TRIM(LEFT(UPPER(TRIM(L3&"")),LEN(UPPER(TRIM(L3&"")))-2)),UPPER(TRIM(L3&"")))) -> K7QM | R3: =IF(Q3="","",IF(ISNUMBER(O3),ROUND(O3,1),IF(AND(ISNUMBER(M3),ISNUMBER(N3)),IF(N3>0,ROUND(M3/N3*100,1),""),""))) -> 50 | S3: =IF(Q3="","",IF(RIGHT(UPPER(TRIM(L3&"")),2)="-N","비경쟁","")) | T3: =IF(Q3="","",IF(COUNTIF(참가자!$A$3:$A$52,Q3)=0,"명단에 없는 코드",""))
A4: =IF(참가자!A4="","",UPPER(TRIM(참가자!A4))) -> R4XT | B4: =IF(A4="","",IF(참가자!B4="","(팀 없음)",TRIM(참가자!B4))) -> 1팀 | C4: =IF(A4="","",IFERROR(INDEX($R$3:$R$102,MATCH(A4,$Q$3:$Q$102,0)),"")) -> 83.3 | D4: =IF(A4="","",IF(C4="","결석",IF(IFERROR(INDEX($S$3:$S$102,MATCH(A4,$Q$3:$Q$102,0)),"")="비경쟁","비경쟁 응시","응시"))) -> 응시 | E4: =IF(A4="","",IF(COUNTIF($Q$3:$Q$102,A4)>1,"중복! 확인","")) | L4: R4XT | M4: 10 | N4: 12 | Q4: =IF(UPPER(TRIM(L4&""))="","",IF(RIGHT(UPPER(TRIM(L4&"")),2)="-N",TRIM(LEFT(UPPER(TRIM(L4&"")),LEN(UPPER(TRIM(L4&"")))-2)),UPPER(TRIM(L4&"")))) -> R4XT | R4: =IF(Q4="","",IF(ISNUMBER(O4),ROUND(O4,1),IF(AND(ISNUMBER(M4),ISNUMBER(N4)),IF(N4>0,ROUND(M4/N4*100,1),""),""))) -> 83.3 | S4: =IF(Q4="","",IF(RIGHT(UPPER(TRIM(L4&"")),2)="-N","비경쟁","")) | T4: =IF(Q4="","",IF(COUNTIF(참가자!$A$3:$A$52,Q4)=0,"명단에 없는 코드",""))
A5: =IF(참가자!A5="","",UPPER(TRIM(참가자!A5))) -> H9WC | B5: =IF(A5="","",IF(참가자!B5="","(팀 없음)",TRIM(참가자!B5))) -> 1팀 | C5: =IF(A5="","",IFERROR(INDEX($R$3:$R$102,MATCH(A5,$Q$3:$Q$102,0)),"")) -> 41.7 | D5: =IF(A5="","",IF(C5="","결석",IF(IFERROR(INDEX($S$3:$S$102,MATCH(A5,$Q$3:$Q$102,0)),"")="비경쟁","비경쟁 응시","응시"))) -> 응시 | E5: =IF(A5="","",IF(COUNTIF($Q$3:$Q$102,A5)>1,"중복! 확인","")) | L5: H9WC | M5: 5 | N5: 12 | Q5: =IF(UPPER(TRIM(L5&""))="","",IF(RIGHT(UPPER(TRIM(L5&"")),2)="-N",TRIM(LEFT(UPPER(TRIM(L5&"")),LEN(UPPER(TRIM(L5&"")))-2)),UPPER(TRIM(L5&"")))) -> H9WC | R5: =IF(Q5="","",IF(ISNUMBER(O5),ROUND(O5,1),IF(AND(ISNUMBER(M5),ISNUMBER(N5)),IF(N5>0,ROUND(M5/N5*100,1),""),""))) -> 41.7 | S5: =IF(Q5="","",IF(RIGHT(UPPER(TRIM(L5&"")),2)="-N","비경쟁","")) | T5: =IF(Q5="","",IF(COUNTIF(참가자!$A$3:$A$52,Q5)=0,"명단에 없는 코드",""))
A6: =IF(참가자!A6="","",UPPER(TRIM(참가자!A6))) -> B3NV | B6: =IF(A6="","",IF(참가자!B6="","(팀 없음)",TRIM(참가자!B6))) -> 2팀 | C6: =IF(A6="","",IFERROR(INDEX($R$3:$R$102,MATCH(A6,$Q$3:$Q$102,0)),"")) -> 75 | D6: =IF(A6="","",IF(C6="","결석",IF(IFERROR(INDEX($S$3:$S$102,MATCH(A6,$Q$3:$Q$102,0)),"")="비경쟁","비경쟁 응시","응시"))) -> 응시 | E6: =IF(A6="","",IF(COUNTIF($Q$3:$Q$102,A6)>1,"중복! 확인","")) -> 중복! 확인 | L6: B3NV | M6: 9 | N6: 12 | Q6: =IF(UPPER(TRIM(L6&""))="","",IF(RIGHT(UPPER(TRIM(L6&"")),2)="-N",TRIM(LEFT(UPPER(TRIM(L6&"")),LEN(UPPER(TRIM(L6&"")))-2)),UPPER(TRIM(L6&"")))) -> B3NV | R6: =IF(Q6="","",IF(ISNUMBER(O6),ROUND(O6,1),IF(AND(ISNUMBER(M6),ISNUMBER(N6)),IF(N6>0,ROUND(M6/N6*100,1),""),""))) -> 75 | S6: =IF(Q6="","",IF(RIGHT(UPPER(TRIM(L6&"")),2)="-N","비경쟁","")) | T6: =IF(Q6="","",IF(COUNTIF(참가자!$A$3:$A$52,Q6)=0,"명단에 없는 코드",""))
A7: =IF(참가자!A7="","",UPPER(TRIM(참가자!A7))) -> Z8LD | B7: =IF(A7="","",IF(참가자!B7="","(팀 없음)",TRIM(참가자!B7))) -> 2팀 | C7: =IF(A7="","",IFERROR(INDEX($R$3:$R$102,MATCH(A7,$Q$3:$Q$102,0)),"")) -> 58.3 | D7: =IF(A7="","",IF(C7="","결석",IF(IFERROR(INDEX($S$3:$S$102,MATCH(A7,$Q$3:$Q$102,0)),"")="비경쟁","비경쟁 응시","응시"))) -> 응시 | E7: =IF(A7="","",IF(COUNTIF($Q$3:$Q$102,A7)>1,"중복! 확인","")) | L7: Z8LD | M7: 7 | N7: 12 | Q7: =IF(UPPER(TRIM(L7&""))="","",IF(RIGHT(UPPER(TRIM(L7&"")),2)="-N",TRIM(LEFT(UPPER(TRIM(L7&"")),LEN(UPPER(TRIM(L7&"")))-2)),UPPER(TRIM(L7&"")))) -> Z8LD | R7: =IF(Q7="","",IF(ISNUMBER(O7),ROUND(O7,1),IF(AND(ISNUMBER(M7),ISNUMBER(N7)),IF(N7>0,ROUND(M7/N7*100,1),""),""))) -> 58.3 | S7: =IF(Q7="","",IF(RIGHT(UPPER(TRIM(L7&"")),2)="-N","비경쟁","")) | T7: =IF(Q7="","",IF(COUNTIF(참가자!$A$3:$A$52,Q7)=0,"명단에 없는 코드",""))
A8: =IF(참가자!A8="","",UPPER(TRIM(참가자!A8))) -> M2PF | B8: =IF(A8="","",IF(참가자!B8="","(팀 없음)",TRIM(참가자!B8))) -> 2팀 | C8: =IF(A8="","",IFERROR(INDEX($R$3:$R$102,MATCH(A8,$Q$3:$Q$102,0)),"")) -> 66.7 | D8: =IF(A8="","",IF(C8="","결석",IF(IFERROR(INDEX($S$3:$S$102,MATCH(A8,$Q$3:$Q$102,0)),"")="비경쟁","비경쟁 응시","응시"))) -> 응시 | E8: =IF(A8="","",IF(COUNTIF($Q$3:$Q$102,A8)>1,"중복! 확인","")) | L8: M2PF | M8: 8 | N8: 12 | Q8: =IF(UPPER(TRIM(L8&""))="","",IF(RIGHT(UPPER(TRIM(L8&"")),2)="-N",TRIM(LEFT(UPPER(TRIM(L8&"")),LEN(UPPER(TRIM(L8&"")))-2)),UPPER(TRIM(L8&"")))) -> M2PF | R8: =IF(Q8="","",IF(ISNUMBER(O8),ROUND(O8,1),IF(AND(ISNUMBER(M8),ISNUMBER(N8)),IF(N8>0,ROUND(M8/N8*100,1),""),""))) -> 66.7 | S8: =IF(Q8="","",IF(RIGHT(UPPER(TRIM(L8&"")),2)="-N","비경쟁","")) | T8: =IF(Q8="","",IF(COUNTIF(참가자!$A$3:$A$52,Q8)=0,"명단에 없는 코드",""))
A9: =IF(참가자!A9="","",UPPER(TRIM(참가자!A9))) -> T6YH | B9: =IF(A9="","",IF(참가자!B9="","(팀 없음)",TRIM(참가자!B9))) -> 3팀 | C9: =IF(A9="","",IFERROR(INDEX($R$3:$R$102,MATCH(A9,$Q$3:$Q$102,0)),"")) -> 66.7 | D9: =IF(A9="","",IF(C9="","결석",IF(IFERROR(INDEX($S$3:$S$102,MATCH(A9,$Q$3:$Q$102,0)),"")="비경쟁","비경쟁 응시","응시"))) -> 응시 | E9: =IF(A9="","",IF(COUNTIF($Q$3:$Q$102,A9)>1,"중복! 확인","")) | L9: T6YH | M9: 8 | N9: 12 | Q9: =IF(UPPER(TRIM(L9&""))="","",IF(RIGHT(UPPER(TRIM(L9&"")),2)="-N",TRIM(LEFT(UPPER(TRIM(L9&"")),LEN(UPPER(TRIM(L9&"")))-2)),UPPER(TRIM(L9&"")))) -> T6YH | R9: =IF(Q9="","",IF(ISNUMBER(O9),ROUND(O9,1),IF(AND(ISNUMBER(M9),ISNUMBER(N9)),IF(N9>0,ROUND(M9/N9*100,1),""),""))) -> 66.7 | S9: =IF(Q9="","",IF(RIGHT(UPPER(TRIM(L9&"")),2)="-N","비경쟁","")) | T9: =IF(Q9="","",IF(COUNTIF(참가자!$A$3:$A$52,Q9)=0,"명단에 없는 코드",""))
A10: =IF(참가자!A10="","",UPPER(TRIM(참가자!A10))) -> C5JR | B10: =IF(A10="","",IF(참가자!B10="","(팀 없음)",TRIM(참가자!B10))) -> 3팀 | C10: =IF(A10="","",IFERROR(INDEX($R$3:$R$102,MATCH(A10,$Q$3:$Q$102,0)),"")) -> 91.7 | D10: =IF(A10="","",IF(C10="","결석",IF(IFERROR(INDEX($S$3:$S$102,MATCH(A10,$Q$3:$Q$102,0)),"")="비경쟁","비경쟁 응시","응시"))) -> 응시 | E10: =IF(A10="","",IF(COUNTIF($Q$3:$Q$102,A10)>1,"중복! 확인","")) | L10: C5JR | M10: 11 | N10: 12 | Q10: =IF(UPPER(TRIM(L10&""))="","",IF(RIGHT(UPPER(TRIM(L10&"")),2)="-N",TRIM(LEFT(UPPER(TRIM(L10&"")),LEN(UPPER(TRIM(L10&"")))-2)),UPPER(TRIM(L10&"")))) -> C5JR | R10: =IF(Q10="","",IF(ISNUMBER(O10),ROUND(O10,1),IF(AND(ISNUMBER(M10),ISNUMBER(N10)),IF(N10>0,ROUND(M10/N10*100,1),""),""))) -> 91.7 | S10: =IF(Q10="","",IF(RIGHT(UPPER(TRIM(L10&"")),2)="-N","비경쟁","")) | T10: =IF(Q10="","",IF(COUNTIF(참가자!$A$3:$A$52,Q10)=0,"명단에 없는 코드",""))
A11: =IF(참가자!A11="","",UPPER(TRIM(참가자!A11))) -> W3KE | B11: =IF(A11="","",IF(참가자!B11="","(팀 없음)",TRIM(참가자!B11))) -> 3팀 | C11: =IF(A11="","",IFERROR(INDEX($R$3:$R$102,MATCH(A11,$Q$3:$Q$102,0)),"")) -> 50 | D11: =IF(A11="","",IF(C11="","결석",IF(IFERROR(INDEX($S$3:$S$102,MATCH(A11,$Q$3:$Q$102,0)),"")="비경쟁","비경쟁 응시","응시"))) -> 응시 | E11: =IF(A11="","",IF(COUNTIF($Q$3:$Q$102,A11)>1,"중복! 확인","")) | L11: W3KE | M11: 6 | N11: 12 | Q11: =IF(UPPER(TRIM(L11&""))="","",IF(RIGHT(UPPER(TRIM(L11&"")),2)="-N",TRIM(LEFT(UPPER(TRIM(L11&"")),LEN(UPPER(TRIM(L11&"")))-2)),UPPER(TRIM(L11&"")))) -> W3KE | R11: =IF(Q11="","",IF(ISNUMBER(O11),ROUND(O11,1),IF(AND(ISNUMBER(M11),ISNUMBER(N11)),IF(N11>0,ROUND(M11/N11*100,1),""),""))) -> 50 | S11: =IF(Q11="","",IF(RIGHT(UPPER(TRIM(L11&"")),2)="-N","비경쟁","")) | T11: =IF(Q11="","",IF(COUNTIF(참가자!$A$3:$A$52,Q11)=0,"명단에 없는 코드",""))
A12: =IF(참가자!A12="","",UPPER(TRIM(참가자!A12))) -> F8UA | B12: =IF(A12="","",IF(참가자!B12="","(팀 없음)",TRIM(참가자!B12))) -> 4팀 | C12: =IF(A12="","",IFERROR(INDEX($R$3:$R$102,MATCH(A12,$Q$3:$Q$102,0)),"")) -> 58.3 | D12: =IF(A12="","",IF(C12="","결석",IF(IFERROR(INDEX($S$3:$S$102,MATCH(A12,$Q$3:$Q$102,0)),"")="비경쟁","비경쟁 응시","응시"))) -> 응시 | E12: =IF(A12="","",IF(COUNTIF($Q$3:$Q$102,A12)>1,"중복! 확인","")) | L12: F8UA | M12: 7 | N12: 12 | Q12: =IF(UPPER(TRIM(L12&""))="","",IF(RIGHT(UPPER(TRIM(L12&"")),2)="-N",TRIM(LEFT(UPPER(TRIM(L12&"")),LEN(UPPER(TRIM(L12&"")))-2)),UPPER(TRIM(L12&"")))) -> F8UA | R12: =IF(Q12="","",IF(ISNUMBER(O12),ROUND(O12,1),IF(AND(ISNUMBER(M12),ISNUMBER(N12)),IF(N12>0,ROUND(M12/N12*100,1),""),""))) -> 58.3 | S12: =IF(Q12="","",IF(RIGHT(UPPER(TRIM(L12&"")),2)="-N","비경쟁","")) | T12: =IF(Q12="","",IF(COUNTIF(참가자!$A$3:$A$52,Q12)=0,"명단에 없는 코드",""))
A13: =IF(참가자!A13="","",UPPER(TRIM(참가자!A13))) -> N4GS | B13: =IF(A13="","",IF(참가자!B13="","(팀 없음)",TRIM(참가자!B13))) -> 4팀 | C13: =IF(A13="","",IFERROR(INDEX($R$3:$R$102,MATCH(A13,$Q$3:$Q$102,0)),"")) | D13: =IF(A13="","",IF(C13="","결석",IF(IFERROR(INDEX($S$3:$S$102,MATCH(A13,$Q$3:$Q$102,0)),"")="비경쟁","비경쟁 응시","응시"))) -> 결석 | E13: =IF(A13="","",IF(COUNTIF($Q$3:$Q$102,A13)>1,"중복! 확인","")) | L13: D7VB | M13: 6 | N13: 12 | Q13: =IF(UPPER(TRIM(L13&""))="","",IF(RIGHT(UPPER(TRIM(L13&"")),2)="-N",TRIM(LEFT(UPPER(TRIM(L13&"")),LEN(UPPER(TRIM(L13&"")))-2)),UPPER(TRIM(L13&"")))) -> D7VB | R13: =IF(Q13="","",IF(ISNUMBER(O13),ROUND(O13,1),IF(AND(ISNUMBER(M13),ISNUMBER(N13)),IF(N13>0,ROUND(M13/N13*100,1),""),""))) -> 50 | S13: =IF(Q13="","",IF(RIGHT(UPPER(TRIM(L13&"")),2)="-N","비경쟁","")) | T13: =IF(Q13="","",IF(COUNTIF(참가자!$A$3:$A$52,Q13)=0,"명단에 없는 코드",""))
A14: =IF(참가자!A14="","",UPPER(TRIM(참가자!A14))) -> D7VB | B14: =IF(A14="","",IF(참가자!B14="","(팀 없음)",TRIM(참가자!B14))) -> 4팀 | C14: =IF(A14="","",IFERROR(INDEX($R$3:$R$102,MATCH(A14,$Q$3:$Q$102,0)),"")) -> 50 | D14: =IF(A14="","",IF(C14="","결석",IF(IFERROR(INDEX($S$3:$S$102,MATCH(A14,$Q$3:$Q$102,0)),"")="비경쟁","비경쟁 응시","응시"))) -> 응시 | E14: =IF(A14="","",IF(COUNTIF($Q$3:$Q$102,A14)>1,"중복! 확인","")) | L14: B3NV | M14: 3 | N14: 12 | Q14: =IF(UPPER(TRIM(L14&""))="","",IF(RIGHT(UPPER(TRIM(L14&"")),2)="-N",TRIM(LEFT(UPPER(TRIM(L14&"")),LEN(UPPER(TRIM(L14&"")))-2)),UPPER(TRIM(L14&"")))) -> B3NV | R14: =IF(Q14="","",IF(ISNUMBER(O14),ROUND(O14,1),IF(AND(ISNUMBER(M14),ISNUMBER(N14)),IF(N14>0,ROUND(M14/N14*100,1),""),""))) -> 25 | S14: =IF(Q14="","",IF(RIGHT(UPPER(TRIM(L14&"")),2)="-N","비경쟁","")) | T14: =IF(Q14="","",IF(COUNTIF(참가자!$A$3:$A$52,Q14)=0,"명단에 없는 코드",""))
A15: =IF(참가자!A15="","",UPPER(TRIM(참가자!A15))) | B15: =IF(A15="","",IF(참가자!B15="","(팀 없음)",TRIM(참가자!B15))) | C15: =IF(A15="","",IFERROR(INDEX($R$3:$R$102,MATCH(A15,$Q$3:$Q$102,0)),"")) | D15: =IF(A15="","",IF(C15="","결석",IF(IFERROR(INDEX($S$3:$S$102,MATCH(A15,$Q$3:$Q$102,0)),"")="비경쟁","비경쟁 응시","응시"))) | E15: =IF(A15="","",IF(COUNTIF($Q$3:$Q$102,A15)>1,"중복! 확인","")) | Q15: =IF(UPPER(TRIM(L15&""))="","",IF(RIGHT(UPPER(TRIM(L15&"")),2)="-N",TRIM(LEFT(UPPER(TRIM(L15&"")),LEN(UPPER(TRIM(L15&"")))-2)),UPPER(TRIM(L15&"")))) | R15: =IF(Q15="","",IF(ISNUMBER(O15),ROUND(O15,1),IF(AND(ISNUMBER(M15),ISNUMBER(N15)),IF(N15>0,ROUND(M15/N15*100,1),""),""))) | S15: =IF(Q15="","",IF(RIGHT(UPPER(TRIM(L15&"")),2)="-N","비경쟁","")) | T15: =IF(Q15="","",IF(COUNTIF(참가자!$A$3:$A$52,Q15)=0,"명단에 없는 코드",""))
A16: =IF(참가자!A16="","",UPPER(TRIM(참가자!A16))) | B16: =IF(A16="","",IF(참가자!B16="","(팀 없음)",TRIM(참가자!B16))) | C16: =IF(A16="","",IFERROR(INDEX($R$3:$R$102,MATCH(A16,$Q$3:$Q$102,0)),"")) | D16: =IF(A16="","",IF(C16="","결석",IF(IFERROR(INDEX($S$3:$S$102,MATCH(A16,$Q$3:$Q$102,0)),"")="비경쟁","비경쟁 응시","응시"))) | E16: =IF(A16="","",IF(COUNTIF($Q$3:$Q$102,A16)>1,"중복! 확인","")) | Q16: =IF(UPPER(TRIM(L16&""))="","",IF(RIGHT(UPPER(TRIM(L16&"")),2)="-N",TRIM(LEFT(UPPER(TRIM(L16&"")),LEN(UPPER(TRIM(L16&"")))-2)),UPPER(TRIM(L16&"")))) | R16: =IF(Q16="","",IF(ISNUMBER(O16),ROUND(O16,1),IF(AND(ISNUMBER(M16),ISNUMBER(N16)),IF(N16>0,ROUND(M16/N16*100,1),""),""))) | S16: =IF(Q16="","",IF(RIGHT(UPPER(TRIM(L16&"")),2)="-N","비경쟁","")) | T16: =IF(Q16="","",IF(COUNTIF(참가자!$A$3:$A$52,Q16)=0,"명단에 없는 코드",""))
A17: =IF(참가자!A17="","",UPPER(TRIM(참가자!A17))) | B17: =IF(A17="","",IF(참가자!B17="","(팀 없음)",TRIM(참가자!B17))) | C17: =IF(A17="","",IFERROR(INDEX($R$3:$R$102,MATCH(A17,$Q$3:$Q$102,0)),"")) | D17: =IF(A17="","",IF(C17="","결석",IF(IFERROR(INDEX($S$3:$S$102,MATCH(A17,$Q$3:$Q$102,0)),"")="비경쟁","비경쟁 응시","응시"))) | E17: =IF(A17="","",IF(COUNTIF($Q$3:$Q$102,A17)>1,"중복! 확인","")) | Q17: =IF(UPPER(TRIM(L17&""))="","",IF(RIGHT(UPPER(TRIM(L17&"")),2)="-N",TRIM(LEFT(UPPER(TRIM(L17&"")),LEN(UPPER(TRIM(L17&"")))-2)),UPPER(TRIM(L17&"")))) | R17: =IF(Q17="","",IF(ISNUMBER(O17),ROUND(O17,1),IF(AND(ISNUMBER(M17),ISNUMBER(N17)),IF(N17>0,ROUND(M17/N17*100,1),""),""))) | S17: =IF(Q17="","",IF(RIGHT(UPPER(TRIM(L17&"")),2)="-N","비경쟁","")) | T17: =IF(Q17="","",IF(COUNTIF(참가자!$A$3:$A$52,Q17)=0,"명단에 없는 코드",""))
A18: =IF(참가자!A18="","",UPPER(TRIM(참가자!A18))) | B18: =IF(A18="","",IF(참가자!B18="","(팀 없음)",TRIM(참가자!B18))) | C18: =IF(A18="","",IFERROR(INDEX($R$3:$R$102,MATCH(A18,$Q$3:$Q$102,0)),"")) | D18: =IF(A18="","",IF(C18="","결석",IF(IFERROR(INDEX($S$3:$S$102,MATCH(A18,$Q$3:$Q$102,0)),"")="비경쟁","비경쟁 응시","응시"))) | E18: =IF(A18="","",IF(COUNTIF($Q$3:$Q$102,A18)>1,"중복! 확인","")) | Q18: =IF(UPPER(TRIM(L18&""))="","",IF(RIGHT(UPPER(TRIM(L18&"")),2)="-N",TRIM(LEFT(UPPER(TRIM(L18&"")),LEN(UPPER(TRIM(L18&"")))-2)),UPPER(TRIM(L18&"")))) | R18: =IF(Q18="","",IF(ISNUMBER(O18),ROUND(O18,1),IF(AND(ISNUMBER(M18),ISNUMBER(N18)),IF(N18>0,ROUND(M18/N18*100,1),""),""))) | S18: =IF(Q18="","",IF(RIGHT(UPPER(TRIM(L18&"")),2)="-N","비경쟁","")) | T18: =IF(Q18="","",IF(COUNTIF(참가자!$A$3:$A$52,Q18)=0,"명단에 없는 코드",""))
A19: =IF(참가자!A19="","",UPPER(TRIM(참가자!A19))) | B19: =IF(A19="","",IF(참가자!B19="","(팀 없음)",TRIM(참가자!B19))) | C19: =IF(A19="","",IFERROR(INDEX($R$3:$R$102,MATCH(A19,$Q$3:$Q$102,0)),"")) | D19: =IF(A19="","",IF(C19="","결석",IF(IFERROR(INDEX($S$3:$S$102,MATCH(A19,$Q$3:$Q$102,0)),"")="비경쟁","비경쟁 응시","응시"))) | E19: =IF(A19="","",IF(COUNTIF($Q$3:$Q$102,A19)>1,"중복! 확인","")) | Q19: =IF(UPPER(TRIM(L19&""))="","",IF(RIGHT(UPPER(TRIM(L19&"")),2)="-N",TRIM(LEFT(UPPER(TRIM(L19&"")),LEN(UPPER(TRIM(L19&"")))-2)),UPPER(TRIM(L19&"")))) | R19: =IF(Q19="","",IF(ISNUMBER(O19),ROUND(O19,1),IF(AND(ISNUMBER(M19),ISNUMBER(N19)),IF(N19>0,ROUND(M19/N19*100,1),""),""))) | S19: =IF(Q19="","",IF(RIGHT(UPPER(TRIM(L19&"")),2)="-N","비경쟁","")) | T19: =IF(Q19="","",IF(COUNTIF(참가자!$A$3:$A$52,Q19)=0,"명단에 없는 코드",""))
A20: =IF(참가자!A20="","",UPPER(TRIM(참가자!A20))) | B20: =IF(A20="","",IF(참가자!B20="","(팀 없음)",TRIM(참가자!B20))) | C20: =IF(A20="","",IFERROR(INDEX($R$3:$R$102,MATCH(A20,$Q$3:$Q$102,0)),"")) | D20: =IF(A20="","",IF(C20="","결석",IF(IFERROR(INDEX($S$3:$S$102,MATCH(A20,$Q$3:$Q$102,0)),"")="비경쟁","비경쟁 응시","응시"))) | E20: =IF(A20="","",IF(COUNTIF($Q$3:$Q$102,A20)>1,"중복! 확인","")) | Q20: =IF(UPPER(TRIM(L20&""))="","",IF(RIGHT(UPPER(TRIM(L20&"")),2)="-N",TRIM(LEFT(UPPER(TRIM(L20&"")),LEN(UPPER(TRIM(L20&"")))-2)),UPPER(TRIM(L20&"")))) | R20: =IF(Q20="","",IF(ISNUMBER(O20),ROUND(O20,1),IF(AND(ISNUMBER(M20),ISNUMBER(N20)),IF(N20>0,ROUND(M20/N20*100,1),""),""))) | S20: =IF(Q20="","",IF(RIGHT(UPPER(TRIM(L20&"")),2)="-N","비경쟁","")) | T20: =IF(Q20="","",IF(COUNTIF(참가자!$A$3:$A$52,Q20)=0,"명단에 없는 코드",""))
A21: =IF(참가자!A21="","",UPPER(TRIM(참가자!A21))) | B21: =IF(A21="","",IF(참가자!B21="","(팀 없음)",TRIM(참가자!B21))) | C21: =IF(A21="","",IFERROR(INDEX($R$3:$R$102,MATCH(A21,$Q$3:$Q$102,0)),"")) | D21: =IF(A21="","",IF(C21="","결석",IF(IFERROR(INDEX($S$3:$S$102,MATCH(A21,$Q$3:$Q$102,0)),"")="비경쟁","비경쟁 응시","응시"))) | E21: =IF(A21="","",IF(COUNTIF($Q$3:$Q$102,A21)>1,"중복! 확인","")) | Q21: =IF(UPPER(TRIM(L21&""))="","",IF(RIGHT(UPPER(TRIM(L21&"")),2)="-N",TRIM(LEFT(UPPER(TRIM(L21&"")),LEN(UPPER(TRIM(L21&"")))-2)),UPPER(TRIM(L21&"")))) | R21: =IF(Q21="","",IF(ISNUMBER(O21),ROUND(O21,1),IF(AND(ISNUMBER(M21),ISNUMBER(N21)),IF(N21>0,ROUND(M21/N21*100,1),""),""))) | S21: =IF(Q21="","",IF(RIGHT(UPPER(TRIM(L21&"")),2)="-N","비경쟁","")) | T21: =IF(Q21="","",IF(COUNTIF(참가자!$A$3:$A$52,Q21)=0,"명단에 없는 코드",""))
A22: =IF(참가자!A22="","",UPPER(TRIM(참가자!A22))) | B22: =IF(A22="","",IF(참가자!B22="","(팀 없음)",TRIM(참가자!B22))) | C22: =IF(A22="","",IFERROR(INDEX($R$3:$R$102,MATCH(A22,$Q$3:$Q$102,0)),"")) | D22: =IF(A22="","",IF(C22="","결석",IF(IFERROR(INDEX($S$3:$S$102,MATCH(A22,$Q$3:$Q$102,0)),"")="비경쟁","비경쟁 응시","응시"))) | E22: =IF(A22="","",IF(COUNTIF($Q$3:$Q$102,A22)>1,"중복! 확인","")) | Q22: =IF(UPPER(TRIM(L22&""))="","",IF(RIGHT(UPPER(TRIM(L22&"")),2)="-N",TRIM(LEFT(UPPER(TRIM(L22&"")),LEN(UPPER(TRIM(L22&"")))-2)),UPPER(TRIM(L22&"")))) | R22: =IF(Q22="","",IF(ISNUMBER(O22),ROUND(O22,1),IF(AND(ISNUMBER(M22),ISNUMBER(N22)),IF(N22>0,ROUND(M22/N22*100,1),""),""))) | S22: =IF(Q22="","",IF(RIGHT(UPPER(TRIM(L22&"")),2)="-N","비경쟁","")) | T22: =IF(Q22="","",IF(COUNTIF(참가자!$A$3:$A$52,Q22)=0,"명단에 없는 코드",""))
A23: =IF(참가자!A23="","",UPPER(TRIM(참가자!A23))) | B23: =IF(A23="","",IF(참가자!B23="","(팀 없음)",TRIM(참가자!B23))) | C23: =IF(A23="","",IFERROR(INDEX($R$3:$R$102,MATCH(A23,$Q$3:$Q$102,0)),"")) | D23: =IF(A23="","",IF(C23="","결석",IF(IFERROR(INDEX($S$3:$S$102,MATCH(A23,$Q$3:$Q$102,0)),"")="비경쟁","비경쟁 응시","응시"))) | E23: =IF(A23="","",IF(COUNTIF($Q$3:$Q$102,A23)>1,"중복! 확인","")) | Q23: =IF(UPPER(TRIM(L23&""))="","",IF(RIGHT(UPPER(TRIM(L23&"")),2)="-N",TRIM(LEFT(UPPER(TRIM(L23&"")),LEN(UPPER(TRIM(L23&"")))-2)),UPPER(TRIM(L23&"")))) | R23: =IF(Q23="","",IF(ISNUMBER(O23),ROUND(O23,1),IF(AND(ISNUMBER(M23),ISNUMBER(N23)),IF(N23>0,ROUND(M23/N23*100,1),""),""))) | S23: =IF(Q23="","",IF(RIGHT(UPPER(TRIM(L23&"")),2)="-N","비경쟁","")) | T23: =IF(Q23="","",IF(COUNTIF(참가자!$A$3:$A$52,Q23)=0,"명단에 없는 코드",""))
A24: =IF(참가자!A24="","",UPPER(TRIM(참가자!A24))) | B24: =IF(A24="","",IF(참가자!B24="","(팀 없음)",TRIM(참가자!B24))) | C24: =IF(A24="","",IFERROR(INDEX($R$3:$R$102,MATCH(A24,$Q$3:$Q$102,0)),"")) | D24: =IF(A24="","",IF(C24="","결석",IF(IFERROR(INDEX($S$3:$S$102,MATCH(A24,$Q$3:$Q$102,0)),"")="비경쟁","비경쟁 응시","응시"))) | E24: =IF(A24="","",IF(COUNTIF($Q$3:$Q$102,A24)>1,"중복! 확인","")) | Q24: =IF(UPPER(TRIM(L24&""))="","",IF(RIGHT(UPPER(TRIM(L24&"")),2)="-N",TRIM(LEFT(UPPER(TRIM(L24&"")),LEN(UPPER(TRIM(L24&"")))-2)),UPPER(TRIM(L24&"")))) | R24: =IF(Q24="","",IF(ISNUMBER(O24),ROUND(O24,1),IF(AND(ISNUMBER(M24),ISNUMBER(N24)),IF(N24>0,ROUND(M24/N24*100,1),""),""))) | S24: =IF(Q24="","",IF(RIGHT(UPPER(TRIM(L24&"")),2)="-N","비경쟁","")) | T24: =IF(Q24="","",IF(COUNTIF(참가자!$A$3:$A$52,Q24)=0,"명단에 없는 코드",""))
A25: =IF(참가자!A25="","",UPPER(TRIM(참가자!A25))) | B25: =IF(A25="","",IF(참가자!B25="","(팀 없음)",TRIM(참가자!B25))) | C25: =IF(A25="","",IFERROR(INDEX($R$3:$R$102,MATCH(A25,$Q$3:$Q$102,0)),"")) | D25: =IF(A25="","",IF(C25="","결석",IF(IFERROR(INDEX($S$3:$S$102,MATCH(A25,$Q$3:$Q$102,0)),"")="비경쟁","비경쟁 응시","응시"))) | E25: =IF(A25="","",IF(COUNTIF($Q$3:$Q$102,A25)>1,"중복! 확인","")) | Q25: =IF(UPPER(TRIM(L25&""))="","",IF(RIGHT(UPPER(TRIM(L25&"")),2)="-N",TRIM(LEFT(UPPER(TRIM(L25&"")),LEN(UPPER(TRIM(L25&"")))-2)),UPPER(TRIM(L25&"")))) | R25: =IF(Q25="","",IF(ISNUMBER(O25),ROUND(O25,1),IF(AND(ISNUMBER(M25),ISNUMBER(N25)),IF(N25>0,ROUND(M25/N25*100,1),""),""))) | S25: =IF(Q25="","",IF(RIGHT(UPPER(TRIM(L25&"")),2)="-N","비경쟁","")) | T25: =IF(Q25="","",IF(COUNTIF(참가자!$A$3:$A$52,Q25)=0,"명단에 없는 코드",""))
A26: =IF(참가자!A26="","",UPPER(TRIM(참가자!A26))) | B26: =IF(A26="","",IF(참가자!B26="","(팀 없음)",TRIM(참가자!B26))) | C26: =IF(A26="","",IFERROR(INDEX($R$3:$R$102,MATCH(A26,$Q$3:$Q$102,0)),"")) | D26: =IF(A26="","",IF(C26="","결석",IF(IFERROR(INDEX($S$3:$S$102,MATCH(A26,$Q$3:$Q$102,0)),"")="비경쟁","비경쟁 응시","응시"))) | E26: =IF(A26="","",IF(COUNTIF($Q$3:$Q$102,A26)>1,"중복! 확인","")) | Q26: =IF(UPPER(TRIM(L26&""))="","",IF(RIGHT(UPPER(TRIM(L26&"")),2)="-N",TRIM(LEFT(UPPER(TRIM(L26&"")),LEN(UPPER(TRIM(L26&"")))-2)),UPPER(TRIM(L26&"")))) | R26: =IF(Q26="","",IF(ISNUMBER(O26),ROUND(O26,1),IF(AND(ISNUMBER(M26),ISNUMBER(N26)),IF(N26>0,ROUND(M26/N26*100,1),""),""))) | S26: =IF(Q26="","",IF(RIGHT(UPPER(TRIM(L26&"")),2)="-N","비경쟁","")) | T26: =IF(Q26="","",IF(COUNTIF(참가자!$A$3:$A$52,Q26)=0,"명단에 없는 코드",""))
... A52: =IF(참가자!A52="","",UPPER(TRIM(참가자!A52))) | B52: =IF(A52="","",IF(참가자!B52="","(팀 없음)",TRIM(참가자!B52))) | C52: =IF(A52="","",IFERROR(INDEX($R$3:$R$102,MATCH(A52,$Q$3:$Q$102,0)),"")) | D52: =IF(A52="","",IF(C52="","결석",IF(IFERROR(INDEX($S$3:$S$102,MATCH(A52,$Q$3:$Q$102,0)),"")="비경쟁","비경쟁 응시","응시"))) | E52: =IF(A52="","",IF(COUNTIF($Q$3:$Q$102,A52)>1,"중복! 확인","")) | Q52: =IF(UPPER(TRIM(L52&""))="","",IF(RIGHT(UPPER(TRIM(L52&"")),2)="-N",TRIM(LEFT(UPPER(TRIM(L52&"")),LEN(UPPER(TRIM(L52&"")))-2)),UPPER(TRIM(L52&"")))) | R52: =IF(Q52="","",IF(ISNUMBER(O52),ROUND(O52,1),IF(AND(ISNUMBER(M52),ISNUMBER(N52)),IF(N52>0,ROUND(M52/N52*100,1),""),""))) | S52: =IF(Q52="","",IF(RIGHT(UPPER(TRIM(L52&"")),2)="-N","비경쟁","")) | T52: =IF(Q52="","",IF(COUNTIF(참가자!$A$3:$A$52,Q52)=0,"명단에 없는 코드",""))
Q53: =IF(UPPER(TRIM(L53&""))="","",IF(RIGHT(UPPER(TRIM(L53&"")),2)="-N",TRIM(LEFT(UPPER(TRIM(L53&"")),LEN(UPPER(TRIM(L53&"")))-2)),UPPER(TRIM(L53&"")))) | R53: =IF(Q53="","",IF(ISNUMBER(O53),ROUND(O53,1),IF(AND(ISNUMBER(M53),ISNUMBER(N53)),IF(N53>0,ROUND(M53/N53*100,1),""),""))) | S53: =IF(Q53="","",IF(RIGHT(UPPER(TRIM(L53&"")),2)="-N","비경쟁","")) | T53: =IF(Q53="","",IF(COUNTIF(참가자!$A$3:$A$52,Q53)=0,"명단에 없는 코드",""))
Q54: =IF(UPPER(TRIM(L54&""))="","",IF(RIGHT(UPPER(TRIM(L54&"")),2)="-N",TRIM(LEFT(UPPER(TRIM(L54&"")),LEN(UPPER(TRIM(L54&"")))-2)),UPPER(TRIM(L54&"")))) | R54: =IF(Q54="","",IF(ISNUMBER(O54),ROUND(O54,1),IF(AND(ISNUMBER(M54),ISNUMBER(N54)),IF(N54>0,ROUND(M54/N54*100,1),""),""))) | S54: =IF(Q54="","",IF(RIGHT(UPPER(TRIM(L54&"")),2)="-N","비경쟁","")) | T54: =IF(Q54="","",IF(COUNTIF(참가자!$A$3:$A$52,Q54)=0,"명단에 없는 코드",""))
Q55: =IF(UPPER(TRIM(L55&""))="","",IF(RIGHT(UPPER(TRIM(L55&"")),2)="-N",TRIM(LEFT(UPPER(TRIM(L55&"")),LEN(UPPER(TRIM(L55&"")))-2)),UPPER(TRIM(L55&"")))) | R55: =IF(Q55="","",IF(ISNUMBER(O55),ROUND(O55,1),IF(AND(ISNUMBER(M55),ISNUMBER(N55)),IF(N55>0,ROUND(M55/N55*100,1),""),""))) | S55: =IF(Q55="","",IF(RIGHT(UPPER(TRIM(L55&"")),2)="-N","비경쟁","")) | T55: =IF(Q55="","",IF(COUNTIF(참가자!$A$3:$A$52,Q55)=0,"명단에 없는 코드",""))
Q56: =IF(UPPER(TRIM(L56&""))="","",IF(RIGHT(UPPER(TRIM(L56&"")),2)="-N",TRIM(LEFT(UPPER(TRIM(L56&"")),LEN(UPPER(TRIM(L56&"")))-2)),UPPER(TRIM(L56&"")))) | R56: =IF(Q56="","",IF(ISNUMBER(O56),ROUND(O56,1),IF(AND(ISNUMBER(M56),ISNUMBER(N56)),IF(N56>0,ROUND(M56/N56*100,1),""),""))) | S56: =IF(Q56="","",IF(RIGHT(UPPER(TRIM(L56&"")),2)="-N","비경쟁","")) | T56: =IF(Q56="","",IF(COUNTIF(참가자!$A$3:$A$52,Q56)=0,"명단에 없는 코드",""))
Q57: =IF(UPPER(TRIM(L57&""))="","",IF(RIGHT(UPPER(TRIM(L57&"")),2)="-N",TRIM(LEFT(UPPER(TRIM(L57&"")),LEN(UPPER(TRIM(L57&"")))-2)),UPPER(TRIM(L57&"")))) | R57: =IF(Q57="","",IF(ISNUMBER(O57),ROUND(O57,1),IF(AND(ISNUMBER(M57),ISNUMBER(N57)),IF(N57>0,ROUND(M57/N57*100,1),""),""))) | S57: =IF(Q57="","",IF(RIGHT(UPPER(TRIM(L57&"")),2)="-N","비경쟁","")) | T57: =IF(Q57="","",IF(COUNTIF(참가자!$A$3:$A$52,Q57)=0,"명단에 없는 코드",""))
Q58: =IF(UPPER(TRIM(L58&""))="","",IF(RIGHT(UPPER(TRIM(L58&"")),2)="-N",TRIM(LEFT(UPPER(TRIM(L58&"")),LEN(UPPER(TRIM(L58&"")))-2)),UPPER(TRIM(L58&"")))) | R58: =IF(Q58="","",IF(ISNUMBER(O58),ROUND(O58,1),IF(AND(ISNUMBER(M58),ISNUMBER(N58)),IF(N58>0,ROUND(M58/N58*100,1),""),""))) | S58: =IF(Q58="","",IF(RIGHT(UPPER(TRIM(L58&"")),2)="-N","비경쟁","")) | T58: =IF(Q58="","",IF(COUNTIF(참가자!$A$3:$A$52,Q58)=0,"명단에 없는 코드",""))
Q59: =IF(UPPER(TRIM(L59&""))="","",IF(RIGHT(UPPER(TRIM(L59&"")),2)="-N",TRIM(LEFT(UPPER(TRIM(L59&"")),LEN(UPPER(TRIM(L59&"")))-2)),UPPER(TRIM(L59&"")))) | R59: =IF(Q59="","",IF(ISNUMBER(O59),ROUND(O59,1),IF(AND(ISNUMBER(M59),ISNUMBER(N59)),IF(N59>0,ROUND(M59/N59*100,1),""),""))) | S59: =IF(Q59="","",IF(RIGHT(UPPER(TRIM(L59&"")),2)="-N","비경쟁","")) | T59: =IF(Q59="","",IF(COUNTIF(참가자!$A$3:$A$52,Q59)=0,"명단에 없는 코드",""))
Q60: =IF(UPPER(TRIM(L60&""))="","",IF(RIGHT(UPPER(TRIM(L60&"")),2)="-N",TRIM(LEFT(UPPER(TRIM(L60&"")),LEN(UPPER(TRIM(L60&"")))-2)),UPPER(TRIM(L60&"")))) | R60: =IF(Q60="","",IF(ISNUMBER(O60),ROUND(O60,1),IF(AND(ISNUMBER(M60),ISNUMBER(N60)),IF(N60>0,ROUND(M60/N60*100,1),""),""))) | S60: =IF(Q60="","",IF(RIGHT(UPPER(TRIM(L60&"")),2)="-N","비경쟁","")) | T60: =IF(Q60="","",IF(COUNTIF(참가자!$A$3:$A$52,Q60)=0,"명단에 없는 코드",""))
Q61: =IF(UPPER(TRIM(L61&""))="","",IF(RIGHT(UPPER(TRIM(L61&"")),2)="-N",TRIM(LEFT(UPPER(TRIM(L61&"")),LEN(UPPER(TRIM(L61&"")))-2)),UPPER(TRIM(L61&"")))) | R61: =IF(Q61="","",IF(ISNUMBER(O61),ROUND(O61,1),IF(AND(ISNUMBER(M61),ISNUMBER(N61)),IF(N61>0,ROUND(M61/N61*100,1),""),""))) | S61: =IF(Q61="","",IF(RIGHT(UPPER(TRIM(L61&"")),2)="-N","비경쟁","")) | T61: =IF(Q61="","",IF(COUNTIF(참가자!$A$3:$A$52,Q61)=0,"명단에 없는 코드",""))
Q62: =IF(UPPER(TRIM(L62&""))="","",IF(RIGHT(UPPER(TRIM(L62&"")),2)="-N",TRIM(LEFT(UPPER(TRIM(L62&"")),LEN(UPPER(TRIM(L62&"")))-2)),UPPER(TRIM(L62&"")))) | R62: =IF(Q62="","",IF(ISNUMBER(O62),ROUND(O62,1),IF(AND(ISNUMBER(M62),ISNUMBER(N62)),IF(N62>0,ROUND(M62/N62*100,1),""),""))) | S62: =IF(Q62="","",IF(RIGHT(UPPER(TRIM(L62&"")),2)="-N","비경쟁","")) | T62: =IF(Q62="","",IF(COUNTIF(참가자!$A$3:$A$52,Q62)=0,"명단에 없는 코드",""))
Q63: =IF(UPPER(TRIM(L63&""))="","",IF(RIGHT(UPPER(TRIM(L63&"")),2)="-N",TRIM(LEFT(UPPER(TRIM(L63&"")),LEN(UPPER(TRIM(L63&"")))-2)),UPPER(TRIM(L63&"")))) | R63: =IF(Q63="","",IF(ISNUMBER(O63),ROUND(O63,1),IF(AND(ISNUMBER(M63),ISNUMBER(N63)),IF(N63>0,ROUND(M63/N63*100,1),""),""))) | S63: =IF(Q63="","",IF(RIGHT(UPPER(TRIM(L63&"")),2)="-N","비경쟁","")) | T63: =IF(Q63="","",IF(COUNTIF(참가자!$A$3:$A$52,Q63)=0,"명단에 없는 코드",""))
Q64: =IF(UPPER(TRIM(L64&""))="","",IF(RIGHT(UPPER(TRIM(L64&"")),2)="-N",TRIM(LEFT(UPPER(TRIM(L64&"")),LEN(UPPER(TRIM(L64&"")))-2)),UPPER(TRIM(L64&"")))) | R64: =IF(Q64="","",IF(ISNUMBER(O64),ROUND(O64,1),IF(AND(ISNUMBER(M64),ISNUMBER(N64)),IF(N64>0,ROUND(M64/N64*100,1),""),""))) | S64: =IF(Q64="","",IF(RIGHT(UPPER(TRIM(L64&"")),2)="-N","비경쟁","")) | T64: =IF(Q64="","",IF(COUNTIF(참가자!$A$3:$A$52,Q64)=0,"명단에 없는 코드",""))
... Q102: =IF(UPPER(TRIM(L102&""))="","",IF(RIGHT(UPPER(TRIM(L102&"")),2)="-N",TRIM(LEFT(UPPER(TRIM(L102&"")),LEN(UPPER(TRIM(L102&"")))-2)),UPPER(TRIM(L102&"")))) | R102: =IF(Q102="","",IF(ISNUMBER(O102),ROUND(O102,1),IF(AND(ISNUMBER(M102),ISNUMBER(N102)),IF(N102>0,ROUND(M102/N102*100,1),""),""))) | S102: =IF(Q102="","",IF(RIGHT(UPPER(TRIM(L102&"")),2)="-N","비경쟁","")) | T102: =IF(Q102="","",IF(COUNTIF(참가자!$A$3:$A$52,Q102)=0,"명단에 없는 코드",""))

Sheet 평가A
A1: 평가A (1회차 공통 평가, 8문항) — 각자의 기준점수 (평가B·C 모두에 고정) | L1: 붙여넣기 영역 (노란 칸, 3행부터)
A2: 참가자 코드 | B2: 팀 | C2: 정답률(%) | D2: 상태 | E2: 중복 점검 | F2: 기준점수(%) | G2: 기준 출처 | H2: 팀 편성 참고(진단+평가A %) | L2: 참가자 코드 | M2: 맞힌 수 | N2: 문항 수 | O2: 정답률(%) | Q2: 정리된 코드(자동) | R2: 계산 정답률(자동) | S2: 비경쟁(자동) | T2: 명단 점검(자동)
A3: =IF(참가자!A3="","",UPPER(TRIM(참가자!A3))) -> K7QM | B3: =IF(A3="","",IF(참가자!B3="","(팀 없음)",TRIM(참가자!B3))) -> 1팀 | C3: =IF(A3="","",IFERROR(INDEX($R$3:$R$102,MATCH(A3,$Q$3:$Q$102,0)),"")) -> 50 | D3: =IF(A3="","",IF(C3="","결석",IF(IFERROR(INDEX($S$3:$S$102,MATCH(A3,$Q$3:$Q$102,0)),"")="비경쟁","비경쟁 응시","응시"))) -> 응시 | E3: =IF(A3="","",IF(COUNTIF($Q$3:$Q$102,A3)>1,"중복! 확인","")) | F3: =IF(A3="","",IF(C3="",IF(ISNUMBER(진단!C3),진단!C3,IF(COUNT($C$3:$C$52)=0,"",ROUND(AVERAGE($C$3:$C$52),1))),IF(AND(USE_DIAG_CHECK=1,ISNUMBER(진단!C3)),IF(ROUND(진단!C3-C3,1)>=DIAG_GAP,ROUND((C3+진단!C3)/2,1),C3),C3))) -> 50 | G3: =IF(A3="","",IF(C3="",IF(F3="","기준점수 없음",IF(ISNUMBER(진단!C3),"진단 대체","응시자 평균")),IF(F3<>C3,"진단 보정","평가A"))) -> 평가A | H3: =IF(A3="","",IF(AND(NOT(ISNUMBER(C3)),NOT(ISNUMBER(진단!C3))),"",ROUND((IF(ISNUMBER(C3),C3*EVAL_ITEMS,0)+IF(ISNUMBER(진단!C3),진단!C3*DIAG_ITEMS,0))/(IF(ISNUMBER(C3),EVAL_ITEMS,0)+IF(ISNUMBER(진단!C3),DIAG_ITEMS,0)),1))) -> 50 | L3: K7QM | M3: 4 | N3: 8 | Q3: =IF(UPPER(TRIM(L3&""))="","",IF(RIGHT(UPPER(TRIM(L3&"")),2)="-N",TRIM(LEFT(UPPER(TRIM(L3&"")),LEN(UPPER(TRIM(L3&"")))-2)),UPPER(TRIM(L3&"")))) -> K7QM | R3: =IF(Q3="","",IF(ISNUMBER(O3),ROUND(O3,1),IF(AND(ISNUMBER(M3),ISNUMBER(N3)),IF(N3>0,ROUND(M3/N3*100,1),""),""))) -> 50 | S3: =IF(Q3="","",IF(RIGHT(UPPER(TRIM(L3&"")),2)="-N","비경쟁","")) | T3: =IF(Q3="","",IF(COUNTIF(참가자!$A$3:$A$52,Q3)=0,"명단에 없는 코드",""))
A4: =IF(참가자!A4="","",UPPER(TRIM(참가자!A4))) -> R4XT | B4: =IF(A4="","",IF(참가자!B4="","(팀 없음)",TRIM(참가자!B4))) -> 1팀 | C4: =IF(A4="","",IFERROR(INDEX($R$3:$R$102,MATCH(A4,$Q$3:$Q$102,0)),"")) -> 87.5 | D4: =IF(A4="","",IF(C4="","결석",IF(IFERROR(INDEX($S$3:$S$102,MATCH(A4,$Q$3:$Q$102,0)),"")="비경쟁","비경쟁 응시","응시"))) -> 응시 | E4: =IF(A4="","",IF(COUNTIF($Q$3:$Q$102,A4)>1,"중복! 확인","")) | F4: =IF(A4="","",IF(C4="",IF(ISNUMBER(진단!C4),진단!C4,IF(COUNT($C$3:$C$52)=0,"",ROUND(AVERAGE($C$3:$C$52),1))),IF(AND(USE_DIAG_CHECK=1,ISNUMBER(진단!C4)),IF(ROUND(진단!C4-C4,1)>=DIAG_GAP,ROUND((C4+진단!C4)/2,1),C4),C4))) -> 87.5 | G4: =IF(A4="","",IF(C4="",IF(F4="","기준점수 없음",IF(ISNUMBER(진단!C4),"진단 대체","응시자 평균")),IF(F4<>C4,"진단 보정","평가A"))) -> 평가A | H4: =IF(A4="","",IF(AND(NOT(ISNUMBER(C4)),NOT(ISNUMBER(진단!C4))),"",ROUND((IF(ISNUMBER(C4),C4*EVAL_ITEMS,0)+IF(ISNUMBER(진단!C4),진단!C4*DIAG_ITEMS,0))/(IF(ISNUMBER(C4),EVAL_ITEMS,0)+IF(ISNUMBER(진단!C4),DIAG_ITEMS,0)),1))) -> 85 | L4: R4XT | M4: 7 | N4: 8 | Q4: =IF(UPPER(TRIM(L4&""))="","",IF(RIGHT(UPPER(TRIM(L4&"")),2)="-N",TRIM(LEFT(UPPER(TRIM(L4&"")),LEN(UPPER(TRIM(L4&"")))-2)),UPPER(TRIM(L4&"")))) -> R4XT | R4: =IF(Q4="","",IF(ISNUMBER(O4),ROUND(O4,1),IF(AND(ISNUMBER(M4),ISNUMBER(N4)),IF(N4>0,ROUND(M4/N4*100,1),""),""))) -> 87.5 | S4: =IF(Q4="","",IF(RIGHT(UPPER(TRIM(L4&"")),2)="-N","비경쟁","")) | T4: =IF(Q4="","",IF(COUNTIF(참가자!$A$3:$A$52,Q4)=0,"명단에 없는 코드",""))
A5: =IF(참가자!A5="","",UPPER(TRIM(참가자!A5))) -> H9WC | B5: =IF(A5="","",IF(참가자!B5="","(팀 없음)",TRIM(참가자!B5))) -> 1팀 | C5: =IF(A5="","",IFERROR(INDEX($R$3:$R$102,MATCH(A5,$Q$3:$Q$102,0)),"")) -> 37.5 | D5: =IF(A5="","",IF(C5="","결석",IF(IFERROR(INDEX($S$3:$S$102,MATCH(A5,$Q$3:$Q$102,0)),"")="비경쟁","비경쟁 응시","응시"))) -> 응시 | E5: =IF(A5="","",IF(COUNTIF($Q$3:$Q$102,A5)>1,"중복! 확인","")) | F5: =IF(A5="","",IF(C5="",IF(ISNUMBER(진단!C5),진단!C5,IF(COUNT($C$3:$C$52)=0,"",ROUND(AVERAGE($C$3:$C$52),1))),IF(AND(USE_DIAG_CHECK=1,ISNUMBER(진단!C5)),IF(ROUND(진단!C5-C5,1)>=DIAG_GAP,ROUND((C5+진단!C5)/2,1),C5),C5))) -> 37.5 | G5: =IF(A5="","",IF(C5="",IF(F5="","기준점수 없음",IF(ISNUMBER(진단!C5),"진단 대체","응시자 평균")),IF(F5<>C5,"진단 보정","평가A"))) -> 평가A | H5: =IF(A5="","",IF(AND(NOT(ISNUMBER(C5)),NOT(ISNUMBER(진단!C5))),"",ROUND((IF(ISNUMBER(C5),C5*EVAL_ITEMS,0)+IF(ISNUMBER(진단!C5),진단!C5*DIAG_ITEMS,0))/(IF(ISNUMBER(C5),EVAL_ITEMS,0)+IF(ISNUMBER(진단!C5),DIAG_ITEMS,0)),1))) -> 40 | L5: H9WC | M5: 3 | N5: 8 | Q5: =IF(UPPER(TRIM(L5&""))="","",IF(RIGHT(UPPER(TRIM(L5&"")),2)="-N",TRIM(LEFT(UPPER(TRIM(L5&"")),LEN(UPPER(TRIM(L5&"")))-2)),UPPER(TRIM(L5&"")))) -> H9WC | R5: =IF(Q5="","",IF(ISNUMBER(O5),ROUND(O5,1),IF(AND(ISNUMBER(M5),ISNUMBER(N5)),IF(N5>0,ROUND(M5/N5*100,1),""),""))) -> 37.5 | S5: =IF(Q5="","",IF(RIGHT(UPPER(TRIM(L5&"")),2)="-N","비경쟁","")) | T5: =IF(Q5="","",IF(COUNTIF(참가자!$A$3:$A$52,Q5)=0,"명단에 없는 코드",""))
A6: =IF(참가자!A6="","",UPPER(TRIM(참가자!A6))) -> B3NV | B6: =IF(A6="","",IF(참가자!B6="","(팀 없음)",TRIM(참가자!B6))) -> 2팀 | C6: =IF(A6="","",IFERROR(INDEX($R$3:$R$102,MATCH(A6,$Q$3:$Q$102,0)),"")) -> 75 | D6: =IF(A6="","",IF(C6="","결석",IF(IFERROR(INDEX($S$3:$S$102,MATCH(A6,$Q$3:$Q$102,0)),"")="비경쟁","비경쟁 응시","응시"))) -> 응시 | E6: =IF(A6="","",IF(COUNTIF($Q$3:$Q$102,A6)>1,"중복! 확인","")) | F6: =IF(A6="","",IF(C6="",IF(ISNUMBER(진단!C6),진단!C6,IF(COUNT($C$3:$C$52)=0,"",ROUND(AVERAGE($C$3:$C$52),1))),IF(AND(USE_DIAG_CHECK=1,ISNUMBER(진단!C6)),IF(ROUND(진단!C6-C6,1)>=DIAG_GAP,ROUND((C6+진단!C6)/2,1),C6),C6))) -> 75 | G6: =IF(A6="","",IF(C6="",IF(F6="","기준점수 없음",IF(ISNUMBER(진단!C6),"진단 대체","응시자 평균")),IF(F6<>C6,"진단 보정","평가A"))) -> 평가A | H6: =IF(A6="","",IF(AND(NOT(ISNUMBER(C6)),NOT(ISNUMBER(진단!C6))),"",ROUND((IF(ISNUMBER(C6),C6*EVAL_ITEMS,0)+IF(ISNUMBER(진단!C6),진단!C6*DIAG_ITEMS,0))/(IF(ISNUMBER(C6),EVAL_ITEMS,0)+IF(ISNUMBER(진단!C6),DIAG_ITEMS,0)),1))) -> 75 | L6: B3NV | M6: 6 | N6: 8 | Q6: =IF(UPPER(TRIM(L6&""))="","",IF(RIGHT(UPPER(TRIM(L6&"")),2)="-N",TRIM(LEFT(UPPER(TRIM(L6&"")),LEN(UPPER(TRIM(L6&"")))-2)),UPPER(TRIM(L6&"")))) -> B3NV | R6: =IF(Q6="","",IF(ISNUMBER(O6),ROUND(O6,1),IF(AND(ISNUMBER(M6),ISNUMBER(N6)),IF(N6>0,ROUND(M6/N6*100,1),""),""))) -> 75 | S6: =IF(Q6="","",IF(RIGHT(UPPER(TRIM(L6&"")),2)="-N","비경쟁","")) | T6: =IF(Q6="","",IF(COUNTIF(참가자!$A$3:$A$52,Q6)=0,"명단에 없는 코드",""))
A7: =IF(참가자!A7="","",UPPER(TRIM(참가자!A7))) -> Z8LD | B7: =IF(A7="","",IF(참가자!B7="","(팀 없음)",TRIM(참가자!B7))) -> 2팀 | C7: =IF(A7="","",IFERROR(INDEX($R$3:$R$102,MATCH(A7,$Q$3:$Q$102,0)),"")) | D7: =IF(A7="","",IF(C7="","결석",IF(IFERROR(INDEX($S$3:$S$102,MATCH(A7,$Q$3:$Q$102,0)),"")="비경쟁","비경쟁 응시","응시"))) -> 결석 | E7: =IF(A7="","",IF(COUNTIF($Q$3:$Q$102,A7)>1,"중복! 확인","")) | F7: =IF(A7="","",IF(C7="",IF(ISNUMBER(진단!C7),진단!C7,IF(COUNT($C$3:$C$52)=0,"",ROUND(AVERAGE($C$3:$C$52),1))),IF(AND(USE_DIAG_CHECK=1,ISNUMBER(진단!C7)),IF(ROUND(진단!C7-C7,1)>=DIAG_GAP,ROUND((C7+진단!C7)/2,1),C7),C7))) -> 58.3 | G7: =IF(A7="","",IF(C7="",IF(F7="","기준점수 없음",IF(ISNUMBER(진단!C7),"진단 대체","응시자 평균")),IF(F7<>C7,"진단 보정","평가A"))) -> 진단 대체 | H7: =IF(A7="","",IF(AND(NOT(ISNUMBER(C7)),NOT(ISNUMBER(진단!C7))),"",ROUND((IF(ISNUMBER(C7),C7*EVAL_ITEMS,0)+IF(ISNUMBER(진단!C7),진단!C7*DIAG_ITEMS,0))/(IF(ISNUMBER(C7),EVAL_ITEMS,0)+IF(ISNUMBER(진단!C7),DIAG_ITEMS,0)),1))) -> 58.3 | L7: M2PF | M7: 5 | N7: 8 | Q7: =IF(UPPER(TRIM(L7&""))="","",IF(RIGHT(UPPER(TRIM(L7&"")),2)="-N",TRIM(LEFT(UPPER(TRIM(L7&"")),LEN(UPPER(TRIM(L7&"")))-2)),UPPER(TRIM(L7&"")))) -> M2PF | R7: =IF(Q7="","",IF(ISNUMBER(O7),ROUND(O7,1),IF(AND(ISNUMBER(M7),ISNUMBER(N7)),IF(N7>0,ROUND(M7/N7*100,1),""),""))) -> 62.5 | S7: =IF(Q7="","",IF(RIGHT(UPPER(TRIM(L7&"")),2)="-N","비경쟁","")) | T7: =IF(Q7="","",IF(COUNTIF(참가자!$A$3:$A$52,Q7)=0,"명단에 없는 코드",""))
A8: =IF(참가자!A8="","",UPPER(TRIM(참가자!A8))) -> M2PF | B8: =IF(A8="","",IF(참가자!B8="","(팀 없음)",TRIM(참가자!B8))) -> 2팀 | C8: =IF(A8="","",IFERROR(INDEX($R$3:$R$102,MATCH(A8,$Q$3:$Q$102,0)),"")) -> 62.5 | D8: =IF(A8="","",IF(C8="","결석",IF(IFERROR(INDEX($S$3:$S$102,MATCH(A8,$Q$3:$Q$102,0)),"")="비경쟁","비경쟁 응시","응시"))) -> 응시 | E8: =IF(A8="","",IF(COUNTIF($Q$3:$Q$102,A8)>1,"중복! 확인","")) | F8: =IF(A8="","",IF(C8="",IF(ISNUMBER(진단!C8),진단!C8,IF(COUNT($C$3:$C$52)=0,"",ROUND(AVERAGE($C$3:$C$52),1))),IF(AND(USE_DIAG_CHECK=1,ISNUMBER(진단!C8)),IF(ROUND(진단!C8-C8,1)>=DIAG_GAP,ROUND((C8+진단!C8)/2,1),C8),C8))) -> 62.5 | G8: =IF(A8="","",IF(C8="",IF(F8="","기준점수 없음",IF(ISNUMBER(진단!C8),"진단 대체","응시자 평균")),IF(F8<>C8,"진단 보정","평가A"))) -> 평가A | H8: =IF(A8="","",IF(AND(NOT(ISNUMBER(C8)),NOT(ISNUMBER(진단!C8))),"",ROUND((IF(ISNUMBER(C8),C8*EVAL_ITEMS,0)+IF(ISNUMBER(진단!C8),진단!C8*DIAG_ITEMS,0))/(IF(ISNUMBER(C8),EVAL_ITEMS,0)+IF(ISNUMBER(진단!C8),DIAG_ITEMS,0)),1))) -> 65 | L8: T6YH | M8: 2 | N8: 8 | Q8: =IF(UPPER(TRIM(L8&""))="","",IF(RIGHT(UPPER(TRIM(L8&"")),2)="-N",TRIM(LEFT(UPPER(TRIM(L8&"")),LEN(UPPER(TRIM(L8&"")))-2)),UPPER(TRIM(L8&"")))) -> T6YH | R8: =IF(Q8="","",IF(ISNUMBER(O8),ROUND(O8,1),IF(AND(ISNUMBER(M8),ISNUMBER(N8)),IF(N8>0,ROUND(M8/N8*100,1),""),""))) -> 25 | S8: =IF(Q8="","",IF(RIGHT(UPPER(TRIM(L8&"")),2)="-N","비경쟁","")) | T8: =IF(Q8="","",IF(COUNTIF(참가자!$A$3:$A$52,Q8)=0,"명단에 없는 코드",""))
A9: =IF(참가자!A9="","",UPPER(TRIM(참가자!A9))) -> T6YH | B9: =IF(A9="","",IF(참가자!B9="","(팀 없음)",TRIM(참가자!B9))) -> 3팀 | C9: =IF(A9="","",IFERROR(INDEX($R$3:$R$102,MATCH(A9,$Q$3:$Q$102,0)),"")) -> 25 | D9: =IF(A9="","",IF(C9="","결석",IF(IFERROR(INDEX($S$3:$S$102,MATCH(A9,$Q$3:$Q$102,0)),"")="비경쟁","비경쟁 응시","응시"))) -> 응시 | E9: =IF(A9="","",IF(COUNTIF($Q$3:$Q$102,A9)>1,"중복! 확인","")) | F9: =IF(A9="","",IF(C9="",IF(ISNUMBER(진단!C9),진단!C9,IF(COUNT($C$3:$C$52)=0,"",ROUND(AVERAGE($C$3:$C$52),1))),IF(AND(USE_DIAG_CHECK=1,ISNUMBER(진단!C9)),IF(ROUND(진단!C9-C9,1)>=DIAG_GAP,ROUND((C9+진단!C9)/2,1),C9),C9))) -> 45.9 | G9: =IF(A9="","",IF(C9="",IF(F9="","기준점수 없음",IF(ISNUMBER(진단!C9),"진단 대체","응시자 평균")),IF(F9<>C9,"진단 보정","평가A"))) -> 진단 보정 | H9: =IF(A9="","",IF(AND(NOT(ISNUMBER(C9)),NOT(ISNUMBER(진단!C9))),"",ROUND((IF(ISNUMBER(C9),C9*EVAL_ITEMS,0)+IF(ISNUMBER(진단!C9),진단!C9*DIAG_ITEMS,0))/(IF(ISNUMBER(C9),EVAL_ITEMS,0)+IF(ISNUMBER(진단!C9),DIAG_ITEMS,0)),1))) -> 50 | L9: C5JR | M9: 8 | N9: 8 | Q9: =IF(UPPER(TRIM(L9&""))="","",IF(RIGHT(UPPER(TRIM(L9&"")),2)="-N",TRIM(LEFT(UPPER(TRIM(L9&"")),LEN(UPPER(TRIM(L9&"")))-2)),UPPER(TRIM(L9&"")))) -> C5JR | R9: =IF(Q9="","",IF(ISNUMBER(O9),ROUND(O9,1),IF(AND(ISNUMBER(M9),ISNUMBER(N9)),IF(N9>0,ROUND(M9/N9*100,1),""),""))) -> 100 | S9: =IF(Q9="","",IF(RIGHT(UPPER(TRIM(L9&"")),2)="-N","비경쟁","")) | T9: =IF(Q9="","",IF(COUNTIF(참가자!$A$3:$A$52,Q9)=0,"명단에 없는 코드",""))
A10: =IF(참가자!A10="","",UPPER(TRIM(참가자!A10))) -> C5JR | B10: =IF(A10="","",IF(참가자!B10="","(팀 없음)",TRIM(참가자!B10))) -> 3팀 | C10: =IF(A10="","",IFERROR(INDEX($R$3:$R$102,MATCH(A10,$Q$3:$Q$102,0)),"")) -> 100 | D10: =IF(A10="","",IF(C10="","결석",IF(IFERROR(INDEX($S$3:$S$102,MATCH(A10,$Q$3:$Q$102,0)),"")="비경쟁","비경쟁 응시","응시"))) -> 응시 | E10: =IF(A10="","",IF(COUNTIF($Q$3:$Q$102,A10)>1,"중복! 확인","")) | F10: =IF(A10="","",IF(C10="",IF(ISNUMBER(진단!C10),진단!C10,IF(COUNT($C$3:$C$52)=0,"",ROUND(AVERAGE($C$3:$C$52),1))),IF(AND(USE_DIAG_CHECK=1,ISNUMBER(진단!C10)),IF(ROUND(진단!C10-C10,1)>=DIAG_GAP,ROUND((C10+진단!C10)/2,1),C10),C10))) -> 100 | G10: =IF(A10="","",IF(C10="",IF(F10="","기준점수 없음",IF(ISNUMBER(진단!C10),"진단 대체","응시자 평균")),IF(F10<>C10,"진단 보정","평가A"))) -> 평가A | H10: =IF(A10="","",IF(AND(NOT(ISNUMBER(C10)),NOT(ISNUMBER(진단!C10))),"",ROUND((IF(ISNUMBER(C10),C10*EVAL_ITEMS,0)+IF(ISNUMBER(진단!C10),진단!C10*DIAG_ITEMS,0))/(IF(ISNUMBER(C10),EVAL_ITEMS,0)+IF(ISNUMBER(진단!C10),DIAG_ITEMS,0)),1))) -> 95 | L10: W3KE | M10: 4 | N10: 8 | Q10: =IF(UPPER(TRIM(L10&""))="","",IF(RIGHT(UPPER(TRIM(L10&"")),2)="-N",TRIM(LEFT(UPPER(TRIM(L10&"")),LEN(UPPER(TRIM(L10&"")))-2)),UPPER(TRIM(L10&"")))) -> W3KE | R10: =IF(Q10="","",IF(ISNUMBER(O10),ROUND(O10,1),IF(AND(ISNUMBER(M10),ISNUMBER(N10)),IF(N10>0,ROUND(M10/N10*100,1),""),""))) -> 50 | S10: =IF(Q10="","",IF(RIGHT(UPPER(TRIM(L10&"")),2)="-N","비경쟁","")) | T10: =IF(Q10="","",IF(COUNTIF(참가자!$A$3:$A$52,Q10)=0,"명단에 없는 코드",""))
A11: =IF(참가자!A11="","",UPPER(TRIM(참가자!A11))) -> W3KE | B11: =IF(A11="","",IF(참가자!B11="","(팀 없음)",TRIM(참가자!B11))) -> 3팀 | C11: =IF(A11="","",IFERROR(INDEX($R$3:$R$102,MATCH(A11,$Q$3:$Q$102,0)),"")) -> 50 | D11: =IF(A11="","",IF(C11="","결석",IF(IFERROR(INDEX($S$3:$S$102,MATCH(A11,$Q$3:$Q$102,0)),"")="비경쟁","비경쟁 응시","응시"))) -> 응시 | E11: =IF(A11="","",IF(COUNTIF($Q$3:$Q$102,A11)>1,"중복! 확인","")) | F11: =IF(A11="","",IF(C11="",IF(ISNUMBER(진단!C11),진단!C11,IF(COUNT($C$3:$C$52)=0,"",ROUND(AVERAGE($C$3:$C$52),1))),IF(AND(USE_DIAG_CHECK=1,ISNUMBER(진단!C11)),IF(ROUND(진단!C11-C11,1)>=DIAG_GAP,ROUND((C11+진단!C11)/2,1),C11),C11))) -> 50 | G11: =IF(A11="","",IF(C11="",IF(F11="","기준점수 없음",IF(ISNUMBER(진단!C11),"진단 대체","응시자 평균")),IF(F11<>C11,"진단 보정","평가A"))) -> 평가A | H11: =IF(A11="","",IF(AND(NOT(ISNUMBER(C11)),NOT(ISNUMBER(진단!C11))),"",ROUND((IF(ISNUMBER(C11),C11*EVAL_ITEMS,0)+IF(ISNUMBER(진단!C11),진단!C11*DIAG_ITEMS,0))/(IF(ISNUMBER(C11),EVAL_ITEMS,0)+IF(ISNUMBER(진단!C11),DIAG_ITEMS,0)),1))) -> 50 | L11: F8UA | M11: 5 | N11: 8 | Q11: =IF(UPPER(TRIM(L11&""))="","",IF(RIGHT(UPPER(TRIM(L11&"")),2)="-N",TRIM(LEFT(UPPER(TRIM(L11&"")),LEN(UPPER(TRIM(L11&"")))-2)),UPPER(TRIM(L11&"")))) -> F8UA | R11: =IF(Q11="","",IF(ISNUMBER(O11),ROUND(O11,1),IF(AND(ISNUMBER(M11),ISNUMBER(N11)),IF(N11>0,ROUND(M11/N11*100,1),""),""))) -> 62.5 | S11: =IF(Q11="","",IF(RIGHT(UPPER(TRIM(L11&"")),2)="-N","비경쟁","")) | T11: =IF(Q11="","",IF(COUNTIF(참가자!$A$3:$A$52,Q11)=0,"명단에 없는 코드",""))
A12: =IF(참가자!A12="","",UPPER(TRIM(참가자!A12))) -> F8UA | B12: =IF(A12="","",IF(참가자!B12="","(팀 없음)",TRIM(참가자!B12))) -> 4팀 | C12: =IF(A12="","",IFERROR(INDEX($R$3:$R$102,MATCH(A12,$Q$3:$Q$102,0)),"")) -> 62.5 | D12: =IF(A12="","",IF(C12="","결석",IF(IFERROR(INDEX($S$3:$S$102,MATCH(A12,$Q$3:$Q$102,0)),"")="비경쟁","비경쟁 응시","응시"))) -> 응시 | E12: =IF(A12="","",IF(COUNTIF($Q$3:$Q$102,A12)>1,"중복! 확인","")) | F12: =IF(A12="","",IF(C12="",IF(ISNUMBER(진단!C12),진단!C12,IF(COUNT($C$3:$C$52)=0,"",ROUND(AVERAGE($C$3:$C$52),1))),IF(AND(USE_DIAG_CHECK=1,ISNUMBER(진단!C12)),IF(ROUND(진단!C12-C12,1)>=DIAG_GAP,ROUND((C12+진단!C12)/2,1),C12),C12))) -> 62.5 | G12: =IF(A12="","",IF(C12="",IF(F12="","기준점수 없음",IF(ISNUMBER(진단!C12),"진단 대체","응시자 평균")),IF(F12<>C12,"진단 보정","평가A"))) -> 평가A | H12: =IF(A12="","",IF(AND(NOT(ISNUMBER(C12)),NOT(ISNUMBER(진단!C12))),"",ROUND((IF(ISNUMBER(C12),C12*EVAL_ITEMS,0)+IF(ISNUMBER(진단!C12),진단!C12*DIAG_ITEMS,0))/(IF(ISNUMBER(C12),EVAL_ITEMS,0)+IF(ISNUMBER(진단!C12),DIAG_ITEMS,0)),1))) -> 60 | L12: D7VB | M12: 3 | N12: 8 | Q12: =IF(UPPER(TRIM(L12&""))="","",IF(RIGHT(UPPER(TRIM(L12&"")),2)="-N",TRIM(LEFT(UPPER(TRIM(L12&"")),LEN(UPPER(TRIM(L12&"")))-2)),UPPER(TRIM(L12&"")))) -> D7VB | R12: =IF(Q12="","",IF(ISNUMBER(O12),ROUND(O12,1),IF(AND(ISNUMBER(M12),ISNUMBER(N12)),IF(N12>0,ROUND(M12/N12*100,1),""),""))) -> 37.5 | S12: =IF(Q12="","",IF(RIGHT(UPPER(TRIM(L12&"")),2)="-N","비경쟁","")) | T12: =IF(Q12="","",IF(COUNTIF(참가자!$A$3:$A$52,Q12)=0,"명단에 없는 코드",""))
A13: =IF(참가자!A13="","",UPPER(TRIM(참가자!A13))) -> N4GS | B13: =IF(A13="","",IF(참가자!B13="","(팀 없음)",TRIM(참가자!B13))) -> 4팀 | C13: =IF(A13="","",IFERROR(INDEX($R$3:$R$102,MATCH(A13,$Q$3:$Q$102,0)),"")) | D13: =IF(A13="","",IF(C13="","결석",IF(IFERROR(INDEX($S$3:$S$102,MATCH(A13,$Q$3:$Q$102,0)),"")="비경쟁","비경쟁 응시","응시"))) -> 결석 | E13: =IF(A13="","",IF(COUNTIF($Q$3:$Q$102,A13)>1,"중복! 확인","")) | F13: =IF(A13="","",IF(C13="",IF(ISNUMBER(진단!C13),진단!C13,IF(COUNT($C$3:$C$52)=0,"",ROUND(AVERAGE($C$3:$C$52),1))),IF(AND(USE_DIAG_CHECK=1,ISNUMBER(진단!C13)),IF(ROUND(진단!C13-C13,1)>=DIAG_GAP,ROUND((C13+진단!C13)/2,1),C13),C13))) -> 58.8 | G13: =IF(A13="","",IF(C13="",IF(F13="","기준점수 없음",IF(ISNUMBER(진단!C13),"진단 대체","응시자 평균")),IF(F13<>C13,"진단 보정","평가A"))) -> 응시자 평균 | H13: =IF(A13="","",IF(AND(NOT(ISNUMBER(C13)),NOT(ISNUMBER(진단!C13))),"",ROUND((IF(ISNUMBER(C13),C13*EVAL_ITEMS,0)+IF(ISNUMBER(진단!C13),진단!C13*DIAG_ITEMS,0))/(IF(ISNUMBER(C13),EVAL_ITEMS,0)+IF(ISNUMBER(진단!C13),DIAG_ITEMS,0)),1))) | Q13: =IF(UPPER(TRIM(L13&""))="","",IF(RIGHT(UPPER(TRIM(L13&"")),2)="-N",TRIM(LEFT(UPPER(TRIM(L13&"")),LEN(UPPER(TRIM(L13&"")))-2)),UPPER(TRIM(L13&"")))) | R13: =IF(Q13="","",IF(ISNUMBER(O13),ROUND(O13,1),IF(AND(ISNUMBER(M13),ISNUMBER(N13)),IF(N13>0,ROUND(M13/N13*100,1),""),""))) | S13: =IF(Q13="","",IF(RIGHT(UPPER(TRIM(L13&"")),2)="-N","비경쟁","")) | T13: =IF(Q13="","",IF(COUNTIF(참가자!$A$3:$A$52,Q13)=0,"명단에 없는 코드",""))
A14: =IF(참가자!A14="","",UPPER(TRIM(참가자!A14))) -> D7VB | B14: =IF(A14="","",IF(참가자!B14="","(팀 없음)",TRIM(참가자!B14))) -> 4팀 | C14: =IF(A14="","",IFERROR(INDEX($R$3:$R$102,MATCH(A14,$Q$3:$Q$102,0)),"")) -> 37.5 | D14: =IF(A14="","",IF(C14="","결석",IF(IFERROR(INDEX($S$3:$S$102,MATCH(A14,$Q$3:$Q$102,0)),"")="비경쟁","비경쟁 응시","응시"))) -> 응시 | E14: =IF(A14="","",IF(COUNTIF($Q$3:$Q$102,A14)>1,"중복! 확인","")) | F14: =IF(A14="","",IF(C14="",IF(ISNUMBER(진단!C14),진단!C14,IF(COUNT($C$3:$C$52)=0,"",ROUND(AVERAGE($C$3:$C$52),1))),IF(AND(USE_DIAG_CHECK=1,ISNUMBER(진단!C14)),IF(ROUND(진단!C14-C14,1)>=DIAG_GAP,ROUND((C14+진단!C14)/2,1),C14),C14))) -> 37.5 | G14: =IF(A14="","",IF(C14="",IF(F14="","기준점수 없음",IF(ISNUMBER(진단!C14),"진단 대체","응시자 평균")),IF(F14<>C14,"진단 보정","평가A"))) -> 평가A | H14: =IF(A14="","",IF(AND(NOT(ISNUMBER(C14)),NOT(ISNUMBER(진단!C14))),"",ROUND((IF(ISNUMBER(C14),C14*EVAL_ITEMS,0)+IF(ISNUMBER(진단!C14),진단!C14*DIAG_ITEMS,0))/(IF(ISNUMBER(C14),EVAL_ITEMS,0)+IF(ISNUMBER(진단!C14),DIAG_ITEMS,0)),1))) -> 45 | Q14: =IF(UPPER(TRIM(L14&""))="","",IF(RIGHT(UPPER(TRIM(L14&"")),2)="-N",TRIM(LEFT(UPPER(TRIM(L14&"")),LEN(UPPER(TRIM(L14&"")))-2)),UPPER(TRIM(L14&"")))) | R14: =IF(Q14="","",IF(ISNUMBER(O14),ROUND(O14,1),IF(AND(ISNUMBER(M14),ISNUMBER(N14)),IF(N14>0,ROUND(M14/N14*100,1),""),""))) | S14: =IF(Q14="","",IF(RIGHT(UPPER(TRIM(L14&"")),2)="-N","비경쟁","")) | T14: =IF(Q14="","",IF(COUNTIF(참가자!$A$3:$A$52,Q14)=0,"명단에 없는 코드",""))
A15: =IF(참가자!A15="","",UPPER(TRIM(참가자!A15))) | B15: =IF(A15="","",IF(참가자!B15="","(팀 없음)",TRIM(참가자!B15))) | C15: =IF(A15="","",IFERROR(INDEX($R$3:$R$102,MATCH(A15,$Q$3:$Q$102,0)),"")) | D15: =IF(A15="","",IF(C15="","결석",IF(IFERROR(INDEX($S$3:$S$102,MATCH(A15,$Q$3:$Q$102,0)),"")="비경쟁","비경쟁 응시","응시"))) | E15: =IF(A15="","",IF(COUNTIF($Q$3:$Q$102,A15)>1,"중복! 확인","")) | F15: =IF(A15="","",IF(C15="",IF(ISNUMBER(진단!C15),진단!C15,IF(COUNT($C$3:$C$52)=0,"",ROUND(AVERAGE($C$3:$C$52),1))),IF(AND(USE_DIAG_CHECK=1,ISNUMBER(진단!C15)),IF(ROUND(진단!C15-C15,1)>=DIAG_GAP,ROUND((C15+진단!C15)/2,1),C15),C15))) | G15: =IF(A15="","",IF(C15="",IF(F15="","기준점수 없음",IF(ISNUMBER(진단!C15),"진단 대체","응시자 평균")),IF(F15<>C15,"진단 보정","평가A"))) | H15: =IF(A15="","",IF(AND(NOT(ISNUMBER(C15)),NOT(ISNUMBER(진단!C15))),"",ROUND((IF(ISNUMBER(C15),C15*EVAL_ITEMS,0)+IF(ISNUMBER(진단!C15),진단!C15*DIAG_ITEMS,0))/(IF(ISNUMBER(C15),EVAL_ITEMS,0)+IF(ISNUMBER(진단!C15),DIAG_ITEMS,0)),1))) | Q15: =IF(UPPER(TRIM(L15&""))="","",IF(RIGHT(UPPER(TRIM(L15&"")),2)="-N",TRIM(LEFT(UPPER(TRIM(L15&"")),LEN(UPPER(TRIM(L15&"")))-2)),UPPER(TRIM(L15&"")))) | R15: =IF(Q15="","",IF(ISNUMBER(O15),ROUND(O15,1),IF(AND(ISNUMBER(M15),ISNUMBER(N15)),IF(N15>0,ROUND(M15/N15*100,1),""),""))) | S15: =IF(Q15="","",IF(RIGHT(UPPER(TRIM(L15&"")),2)="-N","비경쟁","")) | T15: =IF(Q15="","",IF(COUNTIF(참가자!$A$3:$A$52,Q15)=0,"명단에 없는 코드",""))
A16: =IF(참가자!A16="","",UPPER(TRIM(참가자!A16))) | B16: =IF(A16="","",IF(참가자!B16="","(팀 없음)",TRIM(참가자!B16))) | C16: =IF(A16="","",IFERROR(INDEX($R$3:$R$102,MATCH(A16,$Q$3:$Q$102,0)),"")) | D16: =IF(A16="","",IF(C16="","결석",IF(IFERROR(INDEX($S$3:$S$102,MATCH(A16,$Q$3:$Q$102,0)),"")="비경쟁","비경쟁 응시","응시"))) | E16: =IF(A16="","",IF(COUNTIF($Q$3:$Q$102,A16)>1,"중복! 확인","")) | F16: =IF(A16="","",IF(C16="",IF(ISNUMBER(진단!C16),진단!C16,IF(COUNT($C$3:$C$52)=0,"",ROUND(AVERAGE($C$3:$C$52),1))),IF(AND(USE_DIAG_CHECK=1,ISNUMBER(진단!C16)),IF(ROUND(진단!C16-C16,1)>=DIAG_GAP,ROUND((C16+진단!C16)/2,1),C16),C16))) | G16: =IF(A16="","",IF(C16="",IF(F16="","기준점수 없음",IF(ISNUMBER(진단!C16),"진단 대체","응시자 평균")),IF(F16<>C16,"진단 보정","평가A"))) | H16: =IF(A16="","",IF(AND(NOT(ISNUMBER(C16)),NOT(ISNUMBER(진단!C16))),"",ROUND((IF(ISNUMBER(C16),C16*EVAL_ITEMS,0)+IF(ISNUMBER(진단!C16),진단!C16*DIAG_ITEMS,0))/(IF(ISNUMBER(C16),EVAL_ITEMS,0)+IF(ISNUMBER(진단!C16),DIAG_ITEMS,0)),1))) | Q16: =IF(UPPER(TRIM(L16&""))="","",IF(RIGHT(UPPER(TRIM(L16&"")),2)="-N",TRIM(LEFT(UPPER(TRIM(L16&"")),LEN(UPPER(TRIM(L16&"")))-2)),UPPER(TRIM(L16&"")))) | R16: =IF(Q16="","",IF(ISNUMBER(O16),ROUND(O16,1),IF(AND(ISNUMBER(M16),ISNUMBER(N16)),IF(N16>0,ROUND(M16/N16*100,1),""),""))) | S16: =IF(Q16="","",IF(RIGHT(UPPER(TRIM(L16&"")),2)="-N","비경쟁","")) | T16: =IF(Q16="","",IF(COUNTIF(참가자!$A$3:$A$52,Q16)=0,"명단에 없는 코드",""))
A17: =IF(참가자!A17="","",UPPER(TRIM(참가자!A17))) | B17: =IF(A17="","",IF(참가자!B17="","(팀 없음)",TRIM(참가자!B17))) | C17: =IF(A17="","",IFERROR(INDEX($R$3:$R$102,MATCH(A17,$Q$3:$Q$102,0)),"")) | D17: =IF(A17="","",IF(C17="","결석",IF(IFERROR(INDEX($S$3:$S$102,MATCH(A17,$Q$3:$Q$102,0)),"")="비경쟁","비경쟁 응시","응시"))) | E17: =IF(A17="","",IF(COUNTIF($Q$3:$Q$102,A17)>1,"중복! 확인","")) | F17: =IF(A17="","",IF(C17="",IF(ISNUMBER(진단!C17),진단!C17,IF(COUNT($C$3:$C$52)=0,"",ROUND(AVERAGE($C$3:$C$52),1))),IF(AND(USE_DIAG_CHECK=1,ISNUMBER(진단!C17)),IF(ROUND(진단!C17-C17,1)>=DIAG_GAP,ROUND((C17+진단!C17)/2,1),C17),C17))) | G17: =IF(A17="","",IF(C17="",IF(F17="","기준점수 없음",IF(ISNUMBER(진단!C17),"진단 대체","응시자 평균")),IF(F17<>C17,"진단 보정","평가A"))) | H17: =IF(A17="","",IF(AND(NOT(ISNUMBER(C17)),NOT(ISNUMBER(진단!C17))),"",ROUND((IF(ISNUMBER(C17),C17*EVAL_ITEMS,0)+IF(ISNUMBER(진단!C17),진단!C17*DIAG_ITEMS,0))/(IF(ISNUMBER(C17),EVAL_ITEMS,0)+IF(ISNUMBER(진단!C17),DIAG_ITEMS,0)),1))) | Q17: =IF(UPPER(TRIM(L17&""))="","",IF(RIGHT(UPPER(TRIM(L17&"")),2)="-N",TRIM(LEFT(UPPER(TRIM(L17&"")),LEN(UPPER(TRIM(L17&"")))-2)),UPPER(TRIM(L17&"")))) | R17: =IF(Q17="","",IF(ISNUMBER(O17),ROUND(O17,1),IF(AND(ISNUMBER(M17),ISNUMBER(N17)),IF(N17>0,ROUND(M17/N17*100,1),""),""))) | S17: =IF(Q17="","",IF(RIGHT(UPPER(TRIM(L17&"")),2)="-N","비경쟁","")) | T17: =IF(Q17="","",IF(COUNTIF(참가자!$A$3:$A$52,Q17)=0,"명단에 없는 코드",""))
A18: =IF(참가자!A18="","",UPPER(TRIM(참가자!A18))) | B18: =IF(A18="","",IF(참가자!B18="","(팀 없음)",TRIM(참가자!B18))) | C18: =IF(A18="","",IFERROR(INDEX($R$3:$R$102,MATCH(A18,$Q$3:$Q$102,0)),"")) | D18: =IF(A18="","",IF(C18="","결석",IF(IFERROR(INDEX($S$3:$S$102,MATCH(A18,$Q$3:$Q$102,0)),"")="비경쟁","비경쟁 응시","응시"))) | E18: =IF(A18="","",IF(COUNTIF($Q$3:$Q$102,A18)>1,"중복! 확인","")) | F18: =IF(A18="","",IF(C18="",IF(ISNUMBER(진단!C18),진단!C18,IF(COUNT($C$3:$C$52)=0,"",ROUND(AVERAGE($C$3:$C$52),1))),IF(AND(USE_DIAG_CHECK=1,ISNUMBER(진단!C18)),IF(ROUND(진단!C18-C18,1)>=DIAG_GAP,ROUND((C18+진단!C18)/2,1),C18),C18))) | G18: =IF(A18="","",IF(C18="",IF(F18="","기준점수 없음",IF(ISNUMBER(진단!C18),"진단 대체","응시자 평균")),IF(F18<>C18,"진단 보정","평가A"))) | H18: =IF(A18="","",IF(AND(NOT(ISNUMBER(C18)),NOT(ISNUMBER(진단!C18))),"",ROUND((IF(ISNUMBER(C18),C18*EVAL_ITEMS,0)+IF(ISNUMBER(진단!C18),진단!C18*DIAG_ITEMS,0))/(IF(ISNUMBER(C18),EVAL_ITEMS,0)+IF(ISNUMBER(진단!C18),DIAG_ITEMS,0)),1))) | Q18: =IF(UPPER(TRIM(L18&""))="","",IF(RIGHT(UPPER(TRIM(L18&"")),2)="-N",TRIM(LEFT(UPPER(TRIM(L18&"")),LEN(UPPER(TRIM(L18&"")))-2)),UPPER(TRIM(L18&"")))) | R18: =IF(Q18="","",IF(ISNUMBER(O18),ROUND(O18,1),IF(AND(ISNUMBER(M18),ISNUMBER(N18)),IF(N18>0,ROUND(M18/N18*100,1),""),""))) | S18: =IF(Q18="","",IF(RIGHT(UPPER(TRIM(L18&"")),2)="-N","비경쟁","")) | T18: =IF(Q18="","",IF(COUNTIF(참가자!$A$3:$A$52,Q18)=0,"명단에 없는 코드",""))
A19: =IF(참가자!A19="","",UPPER(TRIM(참가자!A19))) | B19: =IF(A19="","",IF(참가자!B19="","(팀 없음)",TRIM(참가자!B19))) | C19: =IF(A19="","",IFERROR(INDEX($R$3:$R$102,MATCH(A19,$Q$3:$Q$102,0)),"")) | D19: =IF(A19="","",IF(C19="","결석",IF(IFERROR(INDEX($S$3:$S$102,MATCH(A19,$Q$3:$Q$102,0)),"")="비경쟁","비경쟁 응시","응시"))) | E19: =IF(A19="","",IF(COUNTIF($Q$3:$Q$102,A19)>1,"중복! 확인","")) | F19: =IF(A19="","",IF(C19="",IF(ISNUMBER(진단!C19),진단!C19,IF(COUNT($C$3:$C$52)=0,"",ROUND(AVERAGE($C$3:$C$52),1))),IF(AND(USE_DIAG_CHECK=1,ISNUMBER(진단!C19)),IF(ROUND(진단!C19-C19,1)>=DIAG_GAP,ROUND((C19+진단!C19)/2,1),C19),C19))) | G19: =IF(A19="","",IF(C19="",IF(F19="","기준점수 없음",IF(ISNUMBER(진단!C19),"진단 대체","응시자 평균")),IF(F19<>C19,"진단 보정","평가A"))) | H19: =IF(A19="","",IF(AND(NOT(ISNUMBER(C19)),NOT(ISNUMBER(진단!C19))),"",ROUND((IF(ISNUMBER(C19),C19*EVAL_ITEMS,0)+IF(ISNUMBER(진단!C19),진단!C19*DIAG_ITEMS,0))/(IF(ISNUMBER(C19),EVAL_ITEMS,0)+IF(ISNUMBER(진단!C19),DIAG_ITEMS,0)),1))) | Q19: =IF(UPPER(TRIM(L19&""))="","",IF(RIGHT(UPPER(TRIM(L19&"")),2)="-N",TRIM(LEFT(UPPER(TRIM(L19&"")),LEN(UPPER(TRIM(L19&"")))-2)),UPPER(TRIM(L19&"")))) | R19: =IF(Q19="","",IF(ISNUMBER(O19),ROUND(O19,1),IF(AND(ISNUMBER(M19),ISNUMBER(N19)),IF(N19>0,ROUND(M19/N19*100,1),""),""))) | S19: =IF(Q19="","",IF(RIGHT(UPPER(TRIM(L19&"")),2)="-N","비경쟁","")) | T19: =IF(Q19="","",IF(COUNTIF(참가자!$A$3:$A$52,Q19)=0,"명단에 없는 코드",""))
A20: =IF(참가자!A20="","",UPPER(TRIM(참가자!A20))) | B20: =IF(A20="","",IF(참가자!B20="","(팀 없음)",TRIM(참가자!B20))) | C20: =IF(A20="","",IFERROR(INDEX($R$3:$R$102,MATCH(A20,$Q$3:$Q$102,0)),"")) | D20: =IF(A20="","",IF(C20="","결석",IF(IFERROR(INDEX($S$3:$S$102,MATCH(A20,$Q$3:$Q$102,0)),"")="비경쟁","비경쟁 응시","응시"))) | E20: =IF(A20="","",IF(COUNTIF($Q$3:$Q$102,A20)>1,"중복! 확인","")) | F20: =IF(A20="","",IF(C20="",IF(ISNUMBER(진단!C20),진단!C20,IF(COUNT($C$3:$C$52)=0,"",ROUND(AVERAGE($C$3:$C$52),1))),IF(AND(USE_DIAG_CHECK=1,ISNUMBER(진단!C20)),IF(ROUND(진단!C20-C20,1)>=DIAG_GAP,ROUND((C20+진단!C20)/2,1),C20),C20))) | G20: =IF(A20="","",IF(C20="",IF(F20="","기준점수 없음",IF(ISNUMBER(진단!C20),"진단 대체","응시자 평균")),IF(F20<>C20,"진단 보정","평가A"))) | H20: =IF(A20="","",IF(AND(NOT(ISNUMBER(C20)),NOT(ISNUMBER(진단!C20))),"",ROUND((IF(ISNUMBER(C20),C20*EVAL_ITEMS,0)+IF(ISNUMBER(진단!C20),진단!C20*DIAG_ITEMS,0))/(IF(ISNUMBER(C20),EVAL_ITEMS,0)+IF(ISNUMBER(진단!C20),DIAG_ITEMS,0)),1))) | Q20: =IF(UPPER(TRIM(L20&""))="","",IF(RIGHT(UPPER(TRIM(L20&"")),2)="-N",TRIM(LEFT(UPPER(TRIM(L20&"")),LEN(UPPER(TRIM(L20&"")))-2)),UPPER(TRIM(L20&"")))) | R20: =IF(Q20="","",IF(ISNUMBER(O20),ROUND(O20,1),IF(AND(ISNUMBER(M20),ISNUMBER(N20)),IF(N20>0,ROUND(M20/N20*100,1),""),""))) | S20: =IF(Q20="","",IF(RIGHT(UPPER(TRIM(L20&"")),2)="-N","비경쟁","")) | T20: =IF(Q20="","",IF(COUNTIF(참가자!$A$3:$A$52,Q20)=0,"명단에 없는 코드",""))
A21: =IF(참가자!A21="","",UPPER(TRIM(참가자!A21))) | B21: =IF(A21="","",IF(참가자!B21="","(팀 없음)",TRIM(참가자!B21))) | C21: =IF(A21="","",IFERROR(INDEX($R$3:$R$102,MATCH(A21,$Q$3:$Q$102,0)),"")) | D21: =IF(A21="","",IF(C21="","결석",IF(IFERROR(INDEX($S$3:$S$102,MATCH(A21,$Q$3:$Q$102,0)),"")="비경쟁","비경쟁 응시","응시"))) | E21: =IF(A21="","",IF(COUNTIF($Q$3:$Q$102,A21)>1,"중복! 확인","")) | F21: =IF(A21="","",IF(C21="",IF(ISNUMBER(진단!C21),진단!C21,IF(COUNT($C$3:$C$52)=0,"",ROUND(AVERAGE($C$3:$C$52),1))),IF(AND(USE_DIAG_CHECK=1,ISNUMBER(진단!C21)),IF(ROUND(진단!C21-C21,1)>=DIAG_GAP,ROUND((C21+진단!C21)/2,1),C21),C21))) | G21: =IF(A21="","",IF(C21="",IF(F21="","기준점수 없음",IF(ISNUMBER(진단!C21),"진단 대체","응시자 평균")),IF(F21<>C21,"진단 보정","평가A"))) | H21: =IF(A21="","",IF(AND(NOT(ISNUMBER(C21)),NOT(ISNUMBER(진단!C21))),"",ROUND((IF(ISNUMBER(C21),C21*EVAL_ITEMS,0)+IF(ISNUMBER(진단!C21),진단!C21*DIAG_ITEMS,0))/(IF(ISNUMBER(C21),EVAL_ITEMS,0)+IF(ISNUMBER(진단!C21),DIAG_ITEMS,0)),1))) | Q21: =IF(UPPER(TRIM(L21&""))="","",IF(RIGHT(UPPER(TRIM(L21&"")),2)="-N",TRIM(LEFT(UPPER(TRIM(L21&"")),LEN(UPPER(TRIM(L21&"")))-2)),UPPER(TRIM(L21&"")))) | R21: =IF(Q21="","",IF(ISNUMBER(O21),ROUND(O21,1),IF(AND(ISNUMBER(M21),ISNUMBER(N21)),IF(N21>0,ROUND(M21/N21*100,1),""),""))) | S21: =IF(Q21="","",IF(RIGHT(UPPER(TRIM(L21&"")),2)="-N","비경쟁","")) | T21: =IF(Q21="","",IF(COUNTIF(참가자!$A$3:$A$52,Q21)=0,"명단에 없는 코드",""))
A22: =IF(참가자!A22="","",UPPER(TRIM(참가자!A22))) | B22: =IF(A22="","",IF(참가자!B22="","(팀 없음)",TRIM(참가자!B22))) | C22: =IF(A22="","",IFERROR(INDEX($R$3:$R$102,MATCH(A22,$Q$3:$Q$102,0)),"")) | D22: =IF(A22="","",IF(C22="","결석",IF(IFERROR(INDEX($S$3:$S$102,MATCH(A22,$Q$3:$Q$102,0)),"")="비경쟁","비경쟁 응시","응시"))) | E22: =IF(A22="","",IF(COUNTIF($Q$3:$Q$102,A22)>1,"중복! 확인","")) | F22: =IF(A22="","",IF(C22="",IF(ISNUMBER(진단!C22),진단!C22,IF(COUNT($C$3:$C$52)=0,"",ROUND(AVERAGE($C$3:$C$52),1))),IF(AND(USE_DIAG_CHECK=1,ISNUMBER(진단!C22)),IF(ROUND(진단!C22-C22,1)>=DIAG_GAP,ROUND((C22+진단!C22)/2,1),C22),C22))) | G22: =IF(A22="","",IF(C22="",IF(F22="","기준점수 없음",IF(ISNUMBER(진단!C22),"진단 대체","응시자 평균")),IF(F22<>C22,"진단 보정","평가A"))) | H22: =IF(A22="","",IF(AND(NOT(ISNUMBER(C22)),NOT(ISNUMBER(진단!C22))),"",ROUND((IF(ISNUMBER(C22),C22*EVAL_ITEMS,0)+IF(ISNUMBER(진단!C22),진단!C22*DIAG_ITEMS,0))/(IF(ISNUMBER(C22),EVAL_ITEMS,0)+IF(ISNUMBER(진단!C22),DIAG_ITEMS,0)),1))) | Q22: =IF(UPPER(TRIM(L22&""))="","",IF(RIGHT(UPPER(TRIM(L22&"")),2)="-N",TRIM(LEFT(UPPER(TRIM(L22&"")),LEN(UPPER(TRIM(L22&"")))-2)),UPPER(TRIM(L22&"")))) | R22: =IF(Q22="","",IF(ISNUMBER(O22),ROUND(O22,1),IF(AND(ISNUMBER(M22),ISNUMBER(N22)),IF(N22>0,ROUND(M22/N22*100,1),""),""))) | S22: =IF(Q22="","",IF(RIGHT(UPPER(TRIM(L22&"")),2)="-N","비경쟁","")) | T22: =IF(Q22="","",IF(COUNTIF(참가자!$A$3:$A$52,Q22)=0,"명단에 없는 코드",""))
A23: =IF(참가자!A23="","",UPPER(TRIM(참가자!A23))) | B23: =IF(A23="","",IF(참가자!B23="","(팀 없음)",TRIM(참가자!B23))) | C23: =IF(A23="","",IFERROR(INDEX($R$3:$R$102,MATCH(A23,$Q$3:$Q$102,0)),"")) | D23: =IF(A23="","",IF(C23="","결석",IF(IFERROR(INDEX($S$3:$S$102,MATCH(A23,$Q$3:$Q$102,0)),"")="비경쟁","비경쟁 응시","응시"))) | E23: =IF(A23="","",IF(COUNTIF($Q$3:$Q$102,A23)>1,"중복! 확인","")) | F23: =IF(A23="","",IF(C23="",IF(ISNUMBER(진단!C23),진단!C23,IF(COUNT($C$3:$C$52)=0,"",ROUND(AVERAGE($C$3:$C$52),1))),IF(AND(USE_DIAG_CHECK=1,ISNUMBER(진단!C23)),IF(ROUND(진단!C23-C23,1)>=DIAG_GAP,ROUND((C23+진단!C23)/2,1),C23),C23))) | G23: =IF(A23="","",IF(C23="",IF(F23="","기준점수 없음",IF(ISNUMBER(진단!C23),"진단 대체","응시자 평균")),IF(F23<>C23,"진단 보정","평가A"))) | H23: =IF(A23="","",IF(AND(NOT(ISNUMBER(C23)),NOT(ISNUMBER(진단!C23))),"",ROUND((IF(ISNUMBER(C23),C23*EVAL_ITEMS,0)+IF(ISNUMBER(진단!C23),진단!C23*DIAG_ITEMS,0))/(IF(ISNUMBER(C23),EVAL_ITEMS,0)+IF(ISNUMBER(진단!C23),DIAG_ITEMS,0)),1))) | Q23: =IF(UPPER(TRIM(L23&""))="","",IF(RIGHT(UPPER(TRIM(L23&"")),2)="-N",TRIM(LEFT(UPPER(TRIM(L23&"")),LEN(UPPER(TRIM(L23&"")))-2)),UPPER(TRIM(L23&"")))) | R23: =IF(Q23="","",IF(ISNUMBER(O23),ROUND(O23,1),IF(AND(ISNUMBER(M23),ISNUMBER(N23)),IF(N23>0,ROUND(M23/N23*100,1),""),""))) | S23: =IF(Q23="","",IF(RIGHT(UPPER(TRIM(L23&"")),2)="-N","비경쟁","")) | T23: =IF(Q23="","",IF(COUNTIF(참가자!$A$3:$A$52,Q23)=0,"명단에 없는 코드",""))
A24: =IF(참가자!A24="","",UPPER(TRIM(참가자!A24))) | B24: =IF(A24="","",IF(참가자!B24="","(팀 없음)",TRIM(참가자!B24))) | C24: =IF(A24="","",IFERROR(INDEX($R$3:$R$102,MATCH(A24,$Q$3:$Q$102,0)),"")) | D24: =IF(A24="","",IF(C24="","결석",IF(IFERROR(INDEX($S$3:$S$102,MATCH(A24,$Q$3:$Q$102,0)),"")="비경쟁","비경쟁 응시","응시"))) | E24: =IF(A24="","",IF(COUNTIF($Q$3:$Q$102,A24)>1,"중복! 확인","")) | F24: =IF(A24="","",IF(C24="",IF(ISNUMBER(진단!C24),진단!C24,IF(COUNT($C$3:$C$52)=0,"",ROUND(AVERAGE($C$3:$C$52),1))),IF(AND(USE_DIAG_CHECK=1,ISNUMBER(진단!C24)),IF(ROUND(진단!C24-C24,1)>=DIAG_GAP,ROUND((C24+진단!C24)/2,1),C24),C24))) | G24: =IF(A24="","",IF(C24="",IF(F24="","기준점수 없음",IF(ISNUMBER(진단!C24),"진단 대체","응시자 평균")),IF(F24<>C24,"진단 보정","평가A"))) | H24: =IF(A24="","",IF(AND(NOT(ISNUMBER(C24)),NOT(ISNUMBER(진단!C24))),"",ROUND((IF(ISNUMBER(C24),C24*EVAL_ITEMS,0)+IF(ISNUMBER(진단!C24),진단!C24*DIAG_ITEMS,0))/(IF(ISNUMBER(C24),EVAL_ITEMS,0)+IF(ISNUMBER(진단!C24),DIAG_ITEMS,0)),1))) | Q24: =IF(UPPER(TRIM(L24&""))="","",IF(RIGHT(UPPER(TRIM(L24&"")),2)="-N",TRIM(LEFT(UPPER(TRIM(L24&"")),LEN(UPPER(TRIM(L24&"")))-2)),UPPER(TRIM(L24&"")))) | R24: =IF(Q24="","",IF(ISNUMBER(O24),ROUND(O24,1),IF(AND(ISNUMBER(M24),ISNUMBER(N24)),IF(N24>0,ROUND(M24/N24*100,1),""),""))) | S24: =IF(Q24="","",IF(RIGHT(UPPER(TRIM(L24&"")),2)="-N","비경쟁","")) | T24: =IF(Q24="","",IF(COUNTIF(참가자!$A$3:$A$52,Q24)=0,"명단에 없는 코드",""))
... A52: =IF(참가자!A52="","",UPPER(TRIM(참가자!A52))) | B52: =IF(A52="","",IF(참가자!B52="","(팀 없음)",TRIM(참가자!B52))) | C52: =IF(A52="","",IFERROR(INDEX($R$3:$R$102,MATCH(A52,$Q$3:$Q$102,0)),"")) | D52: =IF(A52="","",IF(C52="","결석",IF(IFERROR(INDEX($S$3:$S$102,MATCH(A52,$Q$3:$Q$102,0)),"")="비경쟁","비경쟁 응시","응시"))) | E52: =IF(A52="","",IF(COUNTIF($Q$3:$Q$102,A52)>1,"중복! 확인","")) | F52: =IF(A52="","",IF(C52="",IF(ISNUMBER(진단!C52),진단!C52,IF(COUNT($C$3:$C$52)=0,"",ROUND(AVERAGE($C$3:$C$52),1))),IF(AND(USE_DIAG_CHECK=1,ISNUMBER(진단!C52)),IF(ROUND(진단!C52-C52,1)>=DIAG_GAP,ROUND((C52+진단!C52)/2,1),C52),C52))) | G52: =IF(A52="","",IF(C52="",IF(F52="","기준점수 없음",IF(ISNUMBER(진단!C52),"진단 대체","응시자 평균")),IF(F52<>C52,"진단 보정","평가A"))) | H52: =IF(A52="","",IF(AND(NOT(ISNUMBER(C52)),NOT(ISNUMBER(진단!C52))),"",ROUND((IF(ISNUMBER(C52),C52*EVAL_ITEMS,0)+IF(ISNUMBER(진단!C52),진단!C52*DIAG_ITEMS,0))/(IF(ISNUMBER(C52),EVAL_ITEMS,0)+IF(ISNUMBER(진단!C52),DIAG_ITEMS,0)),1))) | Q52: =IF(UPPER(TRIM(L52&""))="","",IF(RIGHT(UPPER(TRIM(L52&"")),2)="-N",TRIM(LEFT(UPPER(TRIM(L52&"")),LEN(UPPER(TRIM(L52&"")))-2)),UPPER(TRIM(L52&"")))) | R52: =IF(Q52="","",IF(ISNUMBER(O52),ROUND(O52,1),IF(AND(ISNUMBER(M52),ISNUMBER(N52)),IF(N52>0,ROUND(M52/N52*100,1),""),""))) | S52: =IF(Q52="","",IF(RIGHT(UPPER(TRIM(L52&"")),2)="-N","비경쟁","")) | T52: =IF(Q52="","",IF(COUNTIF(참가자!$A$3:$A$52,Q52)=0,"명단에 없는 코드",""))
Q53: =IF(UPPER(TRIM(L53&""))="","",IF(RIGHT(UPPER(TRIM(L53&"")),2)="-N",TRIM(LEFT(UPPER(TRIM(L53&"")),LEN(UPPER(TRIM(L53&"")))-2)),UPPER(TRIM(L53&"")))) | R53: =IF(Q53="","",IF(ISNUMBER(O53),ROUND(O53,1),IF(AND(ISNUMBER(M53),ISNUMBER(N53)),IF(N53>0,ROUND(M53/N53*100,1),""),""))) | S53: =IF(Q53="","",IF(RIGHT(UPPER(TRIM(L53&"")),2)="-N","비경쟁","")) | T53: =IF(Q53="","",IF(COUNTIF(참가자!$A$3:$A$52,Q53)=0,"명단에 없는 코드",""))
Q54: =IF(UPPER(TRIM(L54&""))="","",IF(RIGHT(UPPER(TRIM(L54&"")),2)="-N",TRIM(LEFT(UPPER(TRIM(L54&"")),LEN(UPPER(TRIM(L54&"")))-2)),UPPER(TRIM(L54&"")))) | R54: =IF(Q54="","",IF(ISNUMBER(O54),ROUND(O54,1),IF(AND(ISNUMBER(M54),ISNUMBER(N54)),IF(N54>0,ROUND(M54/N54*100,1),""),""))) | S54: =IF(Q54="","",IF(RIGHT(UPPER(TRIM(L54&"")),2)="-N","비경쟁","")) | T54: =IF(Q54="","",IF(COUNTIF(참가자!$A$3:$A$52,Q54)=0,"명단에 없는 코드",""))
Q55: =IF(UPPER(TRIM(L55&""))="","",IF(RIGHT(UPPER(TRIM(L55&"")),2)="-N",TRIM(LEFT(UPPER(TRIM(L55&"")),LEN(UPPER(TRIM(L55&"")))-2)),UPPER(TRIM(L55&"")))) | R55: =IF(Q55="","",IF(ISNUMBER(O55),ROUND(O55,1),IF(AND(ISNUMBER(M55),ISNUMBER(N55)),IF(N55>0,ROUND(M55/N55*100,1),""),""))) | S55: =IF(Q55="","",IF(RIGHT(UPPER(TRIM(L55&"")),2)="-N","비경쟁","")) | T55: =IF(Q55="","",IF(COUNTIF(참가자!$A$3:$A$52,Q55)=0,"명단에 없는 코드",""))
